Workbook

Sheet Scores
A1: Manufacturer | B1: Model | C1: Country | D1: Cost | E1: Mass | F1: Repeat | G1: Payload | H1: DoF | I1: Reach | J1: Arms | K1: Prog Methods | L1: ProgScore | M1: Add. Sens | N1: MatHand | O1: Weld | P1: Assembly | Q1: Disp | R1: Proc | S1: Serv | T1: OtherApp | U1: DegAnthro | V1: Maturity | W1: Cost | X1: Mass | Y1: Repeat | Z1: Payload | AA1: DoF | AB1: Reach | AC1: Arms | AD1: Prog | AE1: Sensor | AF1: Hand | AG1: Weld | AH1: Assem | AI1: Disp | AJ1: Proc | AK1: Serv | AL1: Other | AM1: Anthro | AN1: Maturity | AO1: Score | AP1: Score (cost excl)
A2: ABB | B2: GoFa CRB 15000 - 5kg | C2: Switzerland | D2: 30000 | E2: 28 | F2: 0.02 | G2: 5 | H2: 6 | I2: 950 | J2: 1 | K2: propr, mult | L2: {=INDEX(DataValidation!$B$2:$B$11, _xlfn.XMATCH(K2, DataValidation!$A$2:$A$11))} -> 2 | M2: 0 | N2: 1 | O2: 0 | P2: 1 | Q2: 1 | R2: 0 | S2: 0 | T2: 0 | U2: 0 | V2: 2 | W2: =IF(OR(ISBLANK(D2),W$169="N"),0,(W$170-D2)*W$168) -> 2.6666667 | X2: =IF(OR(ISBLANK(E2),X$169="N"),0,(X$170-E2)*X$168) -> 2.88 | Y2: =IF(OR(ISBLANK(F2),Y$169="N"),0,(Y$170-F2)*Y$168) -> 1.6 | Z2: =IF(OR(ISBLANK(G2),Z$169="N"),0,G2*Z$168) -> 1 | AA2: =IF(OR(ISBLANK(H2),AA$169="N"),0,H2*AA$168) -> 3 | AB2: =IF(OR(ISBLANK(I2),AB$169="N"),0,I2*AB$168) -> 3.1666667 | AC2: =IF(OR(ISBLANK(J2),AC$169="N"),0,J2*AC$168) -> 1 | AD2: =IF(OR(ISBLANK(L2),AD$169="N"),0,L2*AD$168) -> 2 | AE2: =IF(OR(ISBLANK(M2),AE$169="N"),0,M2*AE$168) -> 0 | AF2: =IF(OR(ISBLANK(N2),AF$169="N"),0,N2*AF$168) -> 1 | AG2: =IF(OR(ISBLANK(O2),AG$169="N"),0,O2*AG$168) -> 0 | AH2: =IF(OR(ISBLANK(P2),AH$169="N"),0,P2*AH$168) -> 1 | AI2: =IF(OR(ISBLANK(Q2),AI$169="N"),0,Q2*AI$168) -> 1 | AJ2: =IF(OR(ISBLANK(R2),AJ$169="N"),0,R2*AJ$168) -> 0 | AK2: =IF(OR(ISBLANK(S2),AK$169="N"),0,S2*AK$168) -> 0 | ... AN2: =IF(OR(ISBLANK(V2),AN$169="N"),0,V2*AN$168) -> 4 | AO2: =ROUND(SUM(W2:AN2),1) -> 24.3 | AP2: =ROUND(SUM(X2:AN2),1) -> 21.6 | AQ2: =CORREL(AP2:AP162,D2:D162) -> 0.49731769 | AR2: =CORREL(AO2:AO162,D2:D162) -> 0.2027098
A3: ABB | B3: GoFa CRB 15000 - 10kg | C3: Switzerland | D3: 37500 | E3: 48 | F3: 0.02 | G3: 10 | H3: 6 | I3: 1270 | J3: 1 | K3: propr, mult | L3: {=INDEX(DataValidation!$B$2:$B$11, _xlfn.XMATCH(K3, DataValidation!$A$2:$A$11))} -> 2 | M3: 0 | N3: 1 | O3: 0 | P3: 1 | Q3: 1 | R3: 0 | S3: 0 | T3: 0 | U3: 0 | V3: 2 | W3: =IF(OR(ISBLANK(D3),W$169="N"),0,(W$170-D3)*W$168) -> 1.6666667 | X3: =IF(OR(ISBLANK(E3),X$169="N"),0,(X$170-E3)*X$168) -> 2.08 | Y3: =IF(OR(ISBLANK(F3),Y$169="N"),0,(Y$170-F3)*Y$168) -> 1.6 | Z3: =IF(OR(ISBLANK(G3),Z$169="N"),0,G3*Z$168) -> 2 | AA3: =IF(OR(ISBLANK(H3),AA$169="N"),0,H3*AA$168) -> 3 | AB3: =IF(OR(ISBLANK(I3),AB$169="N"),0,I3*AB$168) -> 4.2333333 | AC3: =IF(OR(ISBLANK(J3),AC$169="N"),0,J3*AC$168) -> 1 | AD3: =IF(OR(ISBLANK(L3),AD$169="N"),0,L3*AD$168) -> 2 | AE3: =IF(OR(ISBLANK(M3),AE$169="N"),0,M3*AE$168) -> 0 | AF3: =IF(OR(ISBLANK(N3),AF$169="N"),0,N3*AF$168) -> 1 | AG3: =IF(OR(ISBLANK(O3),AG$169="N"),0,O3*AG$168) -> 0 | AH3: =IF(OR(ISBLANK(P3),AH$169="N"),0,P3*AH$168) -> 1 | AI3: =IF(OR(ISBLANK(Q3),AI$169="N"),0,Q3*AI$168) -> 1 | AJ3: =IF(OR(ISBLANK(R3),AJ$169="N"),0,R3*AJ$168) -> 0 | AK3: =IF(OR(ISBLANK(S3),AK$169="N"),0,S3*AK$168) -> 0 | ... AN3: =IF(OR(ISBLANK(V3),AN$169="N"),0,V3*AN$168) -> 4 | AO3: =ROUND(SUM(W3:AN3),1) -> 24.6 | AP3: =ROUND(SUM(X3:AN3),1) -> 22.9
A4: ABB | B4: GoFa CRB 15000 - 12kg | C4: Switzerland | D4: 37500 | E4: 51 | F4: 0.02 | G4: 12 | H4: 6 | I4: 1520 | J4: 1 | K4: propr, mult | L4: {=INDEX(DataValidation!$B$2:$B$11, _xlfn.XMATCH(K4, DataValidation!$A$2:$A$11))} -> 2 | M4: 0 | N4: 1 | O4: 0 | P4: 1 | Q4: 1 | R4: 0 | S4: 0 | T4: 0 | U4: 0 | V4: 2 | W4: =IF(OR(ISBLANK(D4),W$169="N"),0,(W$170-D4)*W$168) -> 1.6666667 | X4: =IF(OR(ISBLANK(E4),X$169="N"),0,(X$170-E4)*X$168) -> 1.96 | Y4: =IF(OR(ISBLANK(F4),Y$169="N"),0,(Y$170-F4)*Y$168) -> 1.6 | Z4: =IF(OR(ISBLANK(G4),Z$169="N"),0,G4*Z$168) -> 2.4 | AA4: =IF(OR(ISBLANK(H4),AA$169="N"),0,H4*AA$168) -> 3 | AB4: =IF(OR(ISBLANK(I4),AB$169="N"),0,I4*AB$168) -> 5.0666667 | AC4: =IF(OR(ISBLANK(J4),AC$169="N"),0,J4*AC$168) -> 1 | AD4: =IF(OR(ISBLANK(L4),AD$169="N"),0,L4*AD$168) -> 2 | AE4: =IF(OR(ISBLANK(M4),AE$169="N"),0,M4*AE$168) -> 0 | AF4: =IF(OR(ISBLANK(N4),AF$169="N"),0,N4*AF$168) -> 1 | AG4: =IF(OR(ISBLANK(O4),AG$169="N"),0,O4*AG$168) -> 0 | AH4: =IF(OR(ISBLANK(P4),AH$169="N"),0,P4*AH$168) -> 1 | AI4: =IF(OR(ISBLANK(Q4),AI$169="N"),0,Q4*AI$168) -> 1 | AJ4: =IF(OR(ISBLANK(R4),AJ$169="N"),0,R4*AJ$168) -> 0 | AK4: =IF(OR(ISBLANK(S4),AK$169="N"),0,S4*AK$168) -> 0 | ... AN4: =IF(OR(ISBLANK(V4),AN$169="N"),0,V4*AN$168) -> 4 | AO4: =ROUND(SUM(W4:AN4),1) -> 25.7 | AP4: =ROUND(SUM(X4:AN4),1) -> 24
A5: ABB | B5: YuMi IRB 14050 | C5: Switzerland | D5: 31000 | E5: 9.5 | F5: 0.02 | G5: 0.5 | H5: 7 | I5: 559 | J5: 1 | K5: propr, mult | L5: {=INDEX(DataValidation!$B$2:$B$11, _xlfn.XMATCH(K5, DataValidation!$A$2:$A$11))} -> 2 | M5: 0 | N5: 1 | O5: 0 | P5: 1 | Q5: 0 | R5: 0 | S5: 0 | T5: 0 | U5: 0 | V5: 2 | W5: =IF(OR(ISBLANK(D5),W$169="N"),0,(W$170-D5)*W$168) -> 2.5333333 | X5: =IF(OR(ISBLANK(E5),X$169="N"),0,(X$170-E5)*X$168) -> 3.62 | Y5: =IF(OR(ISBLANK(F5),Y$169="N"),0,(Y$170-F5)*Y$168) -> 1.6 | Z5: =IF(OR(ISBLANK(G5),Z$169="N"),0,G5*Z$168) -> 0.1 | AA5: =IF(OR(ISBLANK(H5),AA$169="N"),0,H5*AA$168) -> 3.5 | AB5: =IF(OR(ISBLANK(I5),AB$169="N"),0,I5*AB$168) -> 1.8633333 | AC5: =IF(OR(ISBLANK(J5),AC$169="N"),0,J5*AC$168) -> 1 | AD5: =IF(OR(ISBLANK(L5),AD$169="N"),0,L5*AD$168) -> 2 | AE5: =IF(OR(ISBLANK(M5),AE$169="N"),0,M5*AE$168) -> 0 | AF5: =IF(OR(ISBLANK(N5),AF$169="N"),0,N5*AF$168) -> 1 | AG5: =IF(OR(ISBLANK(O5),AG$169="N"),0,O5*AG$168) -> 0 | AH5: =IF(OR(ISBLANK(P5),AH$169="N"),0,P5*AH$168) -> 1 | AI5: =IF(OR(ISBLANK(Q5),AI$169="N"),0,Q5*AI$168) -> 0 | AJ5: =IF(OR(ISBLANK(R5),AJ$169="N"),0,R5*AJ$168) -> 0 | AK5: =IF(OR(ISBLANK(S5),AK$169="N"),0,S5*AK$168) -> 0 | ... AN5: =IF(OR(ISBLANK(V5),AN$169="N"),0,V5*AN$168) -> 4 | AO5: =ROUND(SUM(W5:AN5),1) -> 22.2 | AP5: =ROUND(SUM(X5:AN5),1) -> 19.7
A6: ABB | B6: YuMi IRB 14000 | C6: Switzerland | D6: 51000 | E6: 38 | F6: 0.02 | G6: 0.5 | H6: 7 | I6: 559 | J6: 2 | K6: propr, mult | L6: {=INDEX(DataValidation!$B$2:$B$11, _xlfn.XMATCH(K6, DataValidation!$A$2:$A$11))} -> 2 | M6: 0 | N6: 1 | O6: 0 | P6: 1 | Q6: 0 | R6: 0 | S6: 0 | T6: 0 | U6: 0 | V6: 2 | W6: =IF(OR(ISBLANK(D6),W$169="N"),0,(W$170-D6)*W$168) -> -0.13333333 | X6: =IF(OR(ISBLANK(E6),X$169="N"),0,(X$170-E6)*X$168) -> 2.48 | Y6: =IF(OR(ISBLANK(F6),Y$169="N"),0,(Y$170-F6)*Y$168) -> 1.6 | Z6: =IF(OR(ISBLANK(G6),Z$169="N"),0,G6*Z$168) -> 0.1 | AA6: =IF(OR(ISBLANK(H6),AA$169="N"),0,H6*AA$168) -> 3.5 | AB6: =IF(OR(ISBLANK(I6),AB$169="N"),0,I6*AB$168) -> 1.8633333 | AC6: =IF(OR(ISBLANK(J6),AC$169="N"),0,J6*AC$168) -> 2 | AD6: =IF(OR(ISBLANK(L6),AD$169="N"),0,L6*AD$168) -> 2 | AE6: =IF(OR(ISBLANK(M6),AE$169="N"),0,M6*AE$168) -> 0 | AF6: =IF(OR(ISBLANK(N6),AF$169="N"),0,N6*AF$168) -> 1 | AG6: =IF(OR(ISBLANK(O6),AG$169="N"),0,O6*AG$168) -> 0 | AH6: =IF(OR(ISBLANK(P6),AH$169="N"),0,P6*AH$168) -> 1 | AI6: =IF(OR(ISBLANK(Q6),AI$169="N"),0,Q6*AI$168) -> 0 | AJ6: =IF(OR(ISBLANK(R6),AJ$169="N"),0,R6*AJ$168) -> 0 | AK6: =IF(OR(ISBLANK(S6),AK$169="N"),0,S6*AK$168) -> 0 | ... AN6: =IF(OR(ISBLANK(V6),AN$169="N"),0,V6*AN$168) -> 4 | AO6: =ROUND(SUM(W6:AN6),1) -> 19.4 | AP6: =ROUND(SUM(X6:AN6),1) -> 19.5
A7: ABB | B7: SWIFTI CRB 1100-4/0.58 | C7: Switzerland | D7: 29300 | E7: 21 | F7: 0.01 | G7: 4 | H7: 6 | I7: 580 | J7: 1 | K7: propr, mult | L7: {=INDEX(DataValidation!$B$2:$B$11, _xlfn.XMATCH(K7, DataValidation!$A$2:$A$11))} -> 2 | M7: 1 | N7: 1 | O7: 0 | P7: 1 | Q7: 0 | R7: 1 | S7: 0 | T7: 0 | U7: 0 | V7: 2 | W7: =IF(OR(ISBLANK(D7),W$169="N"),0,(W$170-D7)*W$168) -> 2.76 | X7: =IF(OR(ISBLANK(E7),X$169="N"),0,(X$170-E7)*X$168) -> 3.16 | Y7: =IF(OR(ISBLANK(F7),Y$169="N"),0,(Y$170-F7)*Y$168) -> 1.8 | Z7: =IF(OR(ISBLANK(G7),Z$169="N"),0,G7*Z$168) -> 0.8 | AA7: =IF(OR(ISBLANK(H7),AA$169="N"),0,H7*AA$168) -> 3 | AB7: =IF(OR(ISBLANK(I7),AB$169="N"),0,I7*AB$168) -> 1.9333333 | AC7: =IF(OR(ISBLANK(J7),AC$169="N"),0,J7*AC$168) -> 1 | AD7: =IF(OR(ISBLANK(L7),AD$169="N"),0,L7*AD$168) -> 2 | AE7: =IF(OR(ISBLANK(M7),AE$169="N"),0,M7*AE$168) -> 1 | AF7: =IF(OR(ISBLANK(N7),AF$169="N"),0,N7*AF$168) -> 1 | AG7: =IF(OR(ISBLANK(O7),AG$169="N"),0,O7*AG$168) -> 0 | AH7: =IF(OR(ISBLANK(P7),AH$169="N"),0,P7*AH$168) -> 1 | AI7: =IF(OR(ISBLANK(Q7),AI$169="N"),0,Q7*AI$168) -> 0 | AJ7: =IF(OR(ISBLANK(R7),AJ$169="N"),0,R7*AJ$168) -> 1 | AK7: =IF(OR(ISBLANK(S7),AK$169="N"),0,S7*AK$168) -> 0 | ... AN7: =IF(OR(ISBLANK(V7),AN$169="N"),0,V7*AN$168) -> 4 | AO7: =ROUND(SUM(W7:AN7),1) -> 24.5 | AP7: =ROUND(SUM(X7:AN7),1) -> 21.7
A8: ABB | B8: SWIFTI CRB 1300-7/1.4 | C8: Switzerland | D8: 34500 | E8: 75 | F8: 0.03 | G8: 7 | H8: 6 | I8: 580 | J8: 1 | K8: propr, mult | L8: {=INDEX(DataValidation!$B$2:$B$11, _xlfn.XMATCH(K8, DataValidation!$A$2:$A$11))} -> 2 | M8: 1 | N8: 1 | O8: 0 | P8: 1 | Q8: 0 | R8: 1 | S8: 0 | T8: 0 | U8: 0 | V8: 2 | W8: =IF(OR(ISBLANK(D8),W$169="N"),0,(W$170-D8)*W$168) -> 2.0666667 | X8: =IF(OR(ISBLANK(E8),X$169="N"),0,(X$170-E8)*X$168) -> 1 | Y8: =IF(OR(ISBLANK(F8),Y$169="N"),0,(Y$170-F8)*Y$168) -> 1.4 | Z8: =IF(OR(ISBLANK(G8),Z$169="N"),0,G8*Z$168) -> 1.4 | AA8: =IF(OR(ISBLANK(H8),AA$169="N"),0,H8*AA$168) -> 3 | AB8: =IF(OR(ISBLANK(I8),AB$169="N"),0,I8*AB$168) -> 1.9333333 | AC8: =IF(OR(ISBLANK(J8),AC$169="N"),0,J8*AC$168) -> 1 | AD8: =IF(OR(ISBLANK(L8),AD$169="N"),0,L8*AD$168) -> 2 | AE8: =IF(OR(ISBLANK(M8),AE$169="N"),0,M8*AE$168) -> 1 | AF8: =IF(OR(ISBLANK(N8),AF$169="N"),0,N8*AF$168) -> 1 | AG8: =IF(OR(ISBLANK(O8),AG$169="N"),0,O8*AG$168) -> 0 | AH8: =IF(OR(ISBLANK(P8),AH$169="N"),0,P8*AH$168) -> 1 | AI8: =IF(OR(ISBLANK(Q8),AI$169="N"),0,Q8*AI$168) -> 0 | AJ8: =IF(OR(ISBLANK(R8),AJ$169="N"),0,R8*AJ$168) -> 1 | AK8: =IF(OR(ISBLANK(S8),AK$169="N"),0,S8*AK$168) -> 0 | ... AN8: =IF(OR(ISBLANK(V8),AN$169="N"),0,V8*AN$168) -> 4 | AO8: =ROUND(SUM(W8:AN8),1) -> 21.8 | AP8: =ROUND(SUM(X8:AN8),1) -> 19.7
A9: ABB | B9: SWIFTI CRB 1300-10/1.15 | C9: Switzerland | D9: 34500 | E9: 77 | F9: 0.023 | G9: 10 | H9: 6 | I9: 1150 | J9: 1 | K9: propr, mult | L9: {=INDEX(DataValidation!$B$2:$B$11, _xlfn.XMATCH(K9, DataValidation!$A$2:$A$11))} -> 2 | M9: 1 | N9: 1 | O9: 0 | P9: 1 | Q9: 0 | R9: 1 | S9: 0 | T9: 0 | U9: 0 | V9: 2 | W9: =IF(OR(ISBLANK(D9),W$169="N"),0,(W$170-D9)*W$168) -> 2.0666667 | X9: =IF(OR(ISBLANK(E9),X$169="N"),0,(X$170-E9)*X$168) -> 0.92 | Y9: =IF(OR(ISBLANK(F9),Y$169="N"),0,(Y$170-F9)*Y$168) -> 1.54 | Z9: =IF(OR(ISBLANK(G9),Z$169="N"),0,G9*Z$168) -> 2 | AA9: =IF(OR(ISBLANK(H9),AA$169="N"),0,H9*AA$168) -> 3 | AB9: =IF(OR(ISBLANK(I9),AB$169="N"),0,I9*AB$168) -> 3.8333333 | AC9: =IF(OR(ISBLANK(J9),AC$169="N"),0,J9*AC$168) -> 1 | AD9: =IF(OR(ISBLANK(L9),AD$169="N"),0,L9*AD$168) -> 2 | AE9: =IF(OR(ISBLANK(M9),AE$169="N"),0,M9*AE$168) -> 1 | AF9: =IF(OR(ISBLANK(N9),AF$169="N"),0,N9*AF$168) -> 1 | AG9: =IF(OR(ISBLANK(O9),AG$169="N"),0,O9*AG$168) -> 0 | AH9: =IF(OR(ISBLANK(P9),AH$169="N"),0,P9*AH$168) -> 1 | AI9: =IF(OR(ISBLANK(Q9),AI$169="N"),0,Q9*AI$168) -> 0 | AJ9: =IF(OR(ISBLANK(R9),AJ$169="N"),0,R9*AJ$168) -> 1 | AK9: =IF(OR(ISBLANK(S9),AK$169="N"),0,S9*AK$168) -> 0 | ... AN9: =IF(OR(ISBLANK(V9),AN$169="N"),0,V9*AN$168) -> 4 | AO9: =ROUND(SUM(W9:AN9),1) -> 24.4 | AP9: =ROUND(SUM(X9:AN9),1) -> 22.3
A10: ABB | B10: SWIFTI CRB 1300-11/0.9 | C10: Switzerland | D10: 34500 | E10: 79 | F10: 0.02 | G10: 11 | H10: 6 | I10: 900 | J10: 1 | K10: propr, mult | L10: {=INDEX(DataValidation!$B$2:$B$11, _xlfn.XMATCH(K10, DataValidation!$A$2:$A$11))} -> 2 | M10: 1 | N10: 1 | O10: 0 | P10: 1 | Q10: 0 | R10: 1 | S10: 0 | T10: 0 | U10: 0 | V10: 2 | W10: =IF(OR(ISBLANK(D10),W$169="N"),0,(W$170-D10)*W$168) -> 2.0666667 | X10: =IF(OR(ISBLANK(E10),X$169="N"),0,(X$170-E10)*X$168) -> 0.84 | Y10: =IF(OR(ISBLANK(F10),Y$169="N"),0,(Y$170-F10)*Y$168) -> 1.6 | Z10: =IF(OR(ISBLANK(G10),Z$169="N"),0,G10*Z$168) -> 2.2 | AA10: =IF(OR(ISBLANK(H10),AA$169="N"),0,H10*AA$168) -> 3 | AB10: =IF(OR(ISBLANK(I10),AB$169="N"),0,I10*AB$168) -> 3 | AC10: =IF(OR(ISBLANK(J10),AC$169="N"),0,J10*AC$168) -> 1 | AD10: =IF(OR(ISBLANK(L10),AD$169="N"),0,L10*AD$168) -> 2 | AE10: =IF(OR(ISBLANK(M10),AE$169="N"),0,M10*AE$168) -> 1 | AF10: =IF(OR(ISBLANK(N10),AF$169="N"),0,N10*AF$168) -> 1 | AG10: =IF(OR(ISBLANK(O10),AG$169="N"),0,O10*AG$168) -> 0 | AH10: =IF(OR(ISBLANK(P10),AH$169="N"),0,P10*AH$168) -> 1 | AI10: =IF(OR(ISBLANK(Q10),AI$169="N"),0,Q10*AI$168) -> 0 | AJ10: =IF(OR(ISBLANK(R10),AJ$169="N"),0,R10*AJ$168) -> 1 | AK10: =IF(OR(ISBLANK(S10),AK$169="N"),0,S10*AK$168) -> 0 | ... AN10: =IF(OR(ISBLANK(V10),AN$169="N"),0,V10*AN$168) -> 4 | AO10: =ROUND(SUM(W10:AN10),1) -> 23.7 | AP10: =ROUND(SUM(X10:AN10),1) -> 21.6
A11: Agile Robots | B11: Yu 5 Industiral | C11: Germany | D11: 27000 | E11: 31.5 | F11: 0.05 | G11: 7 | H11: 6 | I11: 1000 | J11: 1 | K11: propr, open, mult | L11: {=INDEX(DataValidation!$B$2:$B$11, _xlfn.XMATCH(K11, DataValidation!$A$2:$A$11))} -> 3 | M11: 0 | N11: 1 | O11: 1 | P11: 1 | Q11: 1 | R11: 1 | S11: 0 | T11: 0 | U11: 0 | V11: 2 | W11: =IF(OR(ISBLANK(D11),W$169="N"),0,(W$170-D11)*W$168) -> 3.0666667 | X11: =IF(OR(ISBLANK(E11),X$169="N"),0,(X$170-E11)*X$168) -> 2.74 | Y11: =IF(OR(ISBLANK(F11),Y$169="N"),0,(Y$170-F11)*Y$168) -> 1 | Z11: =IF(OR(ISBLANK(G11),Z$169="N"),0,G11*Z$168) -> 1.4 | AA11: =IF(OR(ISBLANK(H11),AA$169="N"),0,H11*AA$168) -> 3 | AB11: =IF(OR(ISBLANK(I11),AB$169="N"),0,I11*AB$168) -> 3.3333333 | AC11: =IF(OR(ISBLANK(J11),AC$169="N"),0,J11*AC$168) -> 1 | AD11: =IF(OR(ISBLANK(L11),AD$169="N"),0,L11*AD$168) -> 3 | AE11: =IF(OR(ISBLANK(M11),AE$169="N"),0,M11*AE$168) -> 0 | AF11: =IF(OR(ISBLANK(N11),AF$169="N"),0,N11*AF$168) -> 1 | AG11: =IF(OR(ISBLANK(O11),AG$169="N"),0,O11*AG$168) -> 1 | AH11: =IF(OR(ISBLANK(P11),AH$169="N"),0,P11*AH$168) -> 1 | AI11: =IF(OR(ISBLANK(Q11),AI$169="N"),0,Q11*AI$168) -> 1 | AJ11: =IF(OR(ISBLANK(R11),AJ$169="N"),0,R11*AJ$168) -> 1 | AK11: =IF(OR(ISBLANK(S11),AK$169="N"),0,S11*AK$168) -> 0 | ... AN11: =IF(OR(ISBLANK(V11),AN$169="N"),0,V11*AN$168) -> 4 | AO11: =ROUND(SUM(W11:AN11),1) -> 27.5 | AP11: =ROUND(SUM(X11:AN11),1) -> 24.5
A12: AUBO Robotics | B12: AUBO i3 | C12: USA | D12: 18000 | E12: 16 | F12: 0.05 | G12: 3 | H12: 6 | I12: 625 | J12: 1 | K12: open, mult | L12: {=INDEX(DataValidation!$B$2:$B$11, _xlfn.XMATCH(K12, DataValidation!$A$2:$A$11))} -> 3 | M12: 0 | N12: 1 | O12: 0 | P12: 1 | Q12: 1 | R12: 1 | S12: 1 | T12: 1 | U12: 0 | V12: 2 | W12: =IF(OR(ISBLANK(D12),W$169="N"),0,(W$170-D12)*W$168) -> 4.2666667 | X12: =IF(OR(ISBLANK(E12),X$169="N"),0,(X$170-E12)*X$168) -> 3.36 | Y12: =IF(OR(ISBLANK(F12),Y$169="N"),0,(Y$170-F12)*Y$168) -> 1 | Z12: =IF(OR(ISBLANK(G12),Z$169="N"),0,G12*Z$168) -> 0.6 | AA12: =IF(OR(ISBLANK(H12),AA$169="N"),0,H12*AA$168) -> 3 | AB12: =IF(OR(ISBLANK(I12),AB$169="N"),0,I12*AB$168) -> 2.0833333 | AC12: =IF(OR(ISBLANK(J12),AC$169="N"),0,J12*AC$168) -> 1 | AD12: =IF(OR(ISBLANK(L12),AD$169="N"),0,L12*AD$168) -> 3 | AE12: =IF(OR(ISBLANK(M12),AE$169="N"),0,M12*AE$168) -> 0 | AF12: =IF(OR(ISBLANK(N12),AF$169="N"),0,N12*AF$168) -> 1 | AG12: =IF(OR(ISBLANK(O12),AG$169="N"),0,O12*AG$168) -> 0 | AH12: =IF(OR(ISBLANK(P12),AH$169="N"),0,P12*AH$168) -> 1 | AI12: =IF(OR(ISBLANK(Q12),AI$169="N"),0,Q12*AI$168) -> 1 | AJ12: =IF(OR(ISBLANK(R12),AJ$169="N"),0,R12*AJ$168) -> 1 | AK12: =IF(OR(ISBLANK(S12),AK$169="N"),0,S12*AK$168) -> 0.5 | ... AN12: =IF(OR(ISBLANK(V12),AN$169="N"),0,V12*AN$168) -> 4 | AO12: =ROUND(SUM(W12:AN12),1) -> 27.3 | AP12: =ROUND(SUM(X12:AN12),1) -> 23
A13: AUBO Robotics | B13: AUBO i5 | C13: USA | D13: 18000 | E13: 24 | F13: 0.05 | G13: 5 | H13: 6 | I13: 886.5 | J13: 1 | K13: open, mult | L13: {=INDEX(DataValidation!$B$2:$B$11, _xlfn.XMATCH(K13, DataValidation!$A$2:$A$11))} -> 3 | M13: 0 | N13: 1 | O13: 0 | P13: 1 | Q13: 1 | R13: 1 | S13: 1 | T13: 1 | U13: 0 | V13: 2 | W13: =IF(OR(ISBLANK(D13),W$169="N"),0,(W$170-D13)*W$168) -> 4.2666667 | X13: =IF(OR(ISBLANK(E13),X$169="N"),0,(X$170-E13)*X$168) -> 3.04 | Y13: =IF(OR(ISBLANK(F13),Y$169="N"),0,(Y$170-F13)*Y$168) -> 1 | Z13: =IF(OR(ISBLANK(G13),Z$169="N"),0,G13*Z$168) -> 1 | AA13: =IF(OR(ISBLANK(H13),AA$169="N"),0,H13*AA$168) -> 3 | AB13: =IF(OR(ISBLANK(I13),AB$169="N"),0,I13*AB$168) -> 2.955 | AC13: =IF(OR(ISBLANK(J13),AC$169="N"),0,J13*AC$168) -> 1 | AD13: =IF(OR(ISBLANK(L13),AD$169="N"),0,L13*AD$168) -> 3 | AE13: =IF(OR(ISBLANK(M13),AE$169="N"),0,M13*AE$168) -> 0 | AF13: =IF(OR(ISBLANK(N13),AF$169="N"),0,N13*AF$168) -> 1 | AG13: =IF(OR(ISBLANK(O13),AG$169="N"),0,O13*AG$168) -> 0 | AH13: =IF(OR(ISBLANK(P13),AH$169="N"),0,P13*AH$168) -> 1 | AI13: =IF(OR(ISBLANK(Q13),AI$169="N"),0,Q13*AI$168) -> 1 | AJ13: =IF(OR(ISBLANK(R13),AJ$169="N"),0,R13*AJ$168) -> 1 | AK13: =IF(OR(ISBLANK(S13),AK$169="N"),0,S13*AK$168) -> 0.5 | ... AN13: =IF(OR(ISBLANK(V13),AN$169="N"),0,V13*AN$168) -> 4 | AO13: =ROUND(SUM(W13:AN13),1) -> 28.3 | AP13: =ROUND(SUM(X13:AN13),1) -> 24
A14: AUBO Robotics | B14: AUBO i10 | C14: USA | D14: 20000 | E14: 38.5 | F14: 0.1 | G14: 10 | H14: 6 | I14: 1350 | J14: 1 | K14: open, mult | L14: {=INDEX(DataValidation!$B$2:$B$11, _xlfn.XMATCH(K14, DataValidation!$A$2:$A$11))} -> 3 | M14: 0 | N14: 1 | O14: 0 | P14: 1 | Q14: 1 | R14: 1 | S14: 1 | T14: 1 | U14: 0 | V14: 2 | W14: =IF(OR(ISBLANK(D14),W$169="N"),0,(W$170-D14)*W$168) -> 4 | X14: =IF(OR(ISBLANK(E14),X$169="N"),0,(X$170-E14)*X$168) -> 2.46 | Y14: =IF(OR(ISBLANK(F14),Y$169="N"),0,(Y$170-F14)*Y$168) -> 0 | Z14: =IF(OR(ISBLANK(G14),Z$169="N"),0,G14*Z$168) -> 2 | AA14: =IF(OR(ISBLANK(H14),AA$169="N"),0,H14*AA$168) -> 3 | AB14: =IF(OR(ISBLANK(I14),AB$169="N"),0,I14*AB$168) -> 4.5 | AC14: =IF(OR(ISBLANK(J14),AC$169="N"),0,J14*AC$168) -> 1 | AD14: =IF(OR(ISBLANK(L14),AD$169="N"),0,L14*AD$168) -> 3 | AE14: =IF(OR(ISBLANK(M14),AE$169="N"),0,M14*AE$168) -> 0 | AF14: =IF(OR(ISBLANK(N14),AF$169="N"),0,N14*AF$168) -> 1 | AG14: =IF(OR(ISBLANK(O14),AG$169="N"),0,O14*AG$168) -> 0 | AH14: =IF(OR(ISBLANK(P14),AH$169="N"),0,P14*AH$168) -> 1 | AI14: =IF(OR(ISBLANK(Q14),AI$169="N"),0,Q14*AI$168) -> 1 | AJ14: =IF(OR(ISBLANK(R14),AJ$169="N"),0,R14*AJ$168) -> 1 | AK14: =IF(OR(ISBLANK(S14),AK$169="N"),0,S14*AK$168) -> 0.5 | ... AN14: =IF(OR(ISBLANK(V14),AN$169="N"),0,V14*AN$168) -> 4 | AO14: =ROUND(SUM(W14:AN14),1) -> 29 | AP14: =ROUND(SUM(X14:AN14),1) -> 25
... A16: AUBO Robotics | B16: AUBO i20 | C16: USA | D16: 30000 | E16: 63 | F16: 0.1 | G16: 20 | H16: 6 | I16: 1650 | J16: 1 | K16: open, mult | L16: {=INDEX(DataValidation!$B$2:$B$11, _xlfn.XMATCH(K16, DataValidation!$A$2:$A$11))} -> 3 | M16: 0 | N16: 1 | O16: 0 | P16: 1 | Q16: 1 | R16: 1 | S16: 1 | T16: 1 | U16: 0 | V16: 2 | W16: =IF(OR(ISBLANK(D16),W$169="N"),0,(W$170-D16)*W$168) -> 2.6666667 | X16: =IF(OR(ISBLANK(E16),X$169="N"),0,(X$170-E16)*X$168) -> 1.48 | Y16: =IF(OR(ISBLANK(F16),Y$169="N"),0,(Y$170-F16)*Y$168) -> 0 | Z16: =IF(OR(ISBLANK(G16),Z$169="N"),0,G16*Z$168) -> 4 | AA16: =IF(OR(ISBLANK(H16),AA$169="N"),0,H16*AA$168) -> 3 | AB16: =IF(OR(ISBLANK(I16),AB$169="N"),0,I16*AB$168) -> 5.5 | AC16: =IF(OR(ISBLANK(J16),AC$169="N"),0,J16*AC$168) -> 1 | AD16: =IF(OR(ISBLANK(L16),AD$169="N"),0,L16*AD$168) -> 3 | AE16: =IF(OR(ISBLANK(M16),AE$169="N"),0,M16*AE$168) -> 0 | AF16: =IF(OR(ISBLANK(N16),AF$169="N"),0,N16*AF$168) -> 1 | AG16: =IF(OR(ISBLANK(O16),AG$169="N"),0,O16*AG$168) -> 0 | AH16: =IF(OR(ISBLANK(P16),AH$169="N"),0,P16*AH$168) -> 1 | AI16: =IF(OR(ISBLANK(Q16),AI$169="N"),0,Q16*AI$168) -> 1 | AJ16: =IF(OR(ISBLANK(R16),AJ$169="N"),0,R16*AJ$168) -> 1 | AK16: =IF(OR(ISBLANK(S16),AK$169="N"),0,S16*AK$168) -> 0.5 | ... AN16: =IF(OR(ISBLANK(V16),AN$169="N"),0,V16*AN$168) -> 4 | AO16: =ROUND(SUM(W16:AN16),1) -> 29.6 | AP16: =ROUND(SUM(X16:AN16),1) -> 27
A17: Brooks Automation | B17: PreciseFlex DDR 4 | C17: USA | E17: 46 | F17: 0.02 | G17: 8 | H17: 4 | I17: 1793 | J17: 1 | K17: propr, mult | L17: {=INDEX(DataValidation!$B$2:$B$11, _xlfn.XMATCH(K17, DataValidation!$A$2:$A$11))} -> 2 | M17: 0 | N17: 1 | O17: 0 | P17: 1 | Q17: 1 | R17: 1 | S17: 0 | T17: 1 | U17: 0 | V17: 2 | W17: =IF(OR(ISBLANK(D17),W$169="N"),0,(W$170-D17)*W$168) -> 0 | X17: =IF(OR(ISBLANK(E17),X$169="N"),0,(X$170-E17)*X$168) -> 2.16 | Y17: =IF(OR(ISBLANK(F17),Y$169="N"),0,(Y$170-F17)*Y$168) -> 1.6 | Z17: =IF(OR(ISBLANK(G17),Z$169="N"),0,G17*Z$168) -> 1.6 | AA17: =IF(OR(ISBLANK(H17),AA$169="N"),0,H17*AA$168) -> 2 | AB17: =IF(OR(ISBLANK(I17),AB$169="N"),0,I17*AB$168) -> 5.9766667 | AC17: =IF(OR(ISBLANK(J17),AC$169="N"),0,J17*AC$168) -> 1 | AD17: =IF(OR(ISBLANK(L17),AD$169="N"),0,L17*AD$168) -> 2 | AE17: =IF(OR(ISBLANK(M17),AE$169="N"),0,M17*AE$168) -> 0 | AF17: =IF(OR(ISBLANK(N17),AF$169="N"),0,N17*AF$168) -> 1 | AG17: =IF(OR(ISBLANK(O17),AG$169="N"),0,O17*AG$168) -> 0 | AH17: =IF(OR(ISBLANK(P17),AH$169="N"),0,P17*AH$168) -> 1 | AI17: =IF(OR(ISBLANK(Q17),AI$169="N"),0,Q17*AI$168) -> 1 | AJ17: =IF(OR(ISBLANK(R17),AJ$169="N"),0,R17*AJ$168) -> 1 | AK17: =IF(OR(ISBLANK(S17),AK$169="N"),0,S17*AK$168) -> 0 | ... AN17: =IF(OR(ISBLANK(V17),AN$169="N"),0,V17*AN$168) -> 4 | AO17: =ROUND(SUM(W17:AN17),1) -> 24.8 | AP17: =ROUND(SUM(X17:AN17),1) -> 24.8
A18: Brooks Automation | B18: PreciseFlex DDR 6 | C18: USA | E18: 46 | F18: 0.02 | G18: 6 | H18: 6 | I18: 1793 | J18: 1 | K18: propr, mult | L18: {=INDEX(DataValidation!$B$2:$B$11, _xlfn.XMATCH(K18, DataValidation!$A$2:$A$11))} -> 2 | M18: 0 | N18: 1 | O18: 0 | P18: 1 | Q18: 1 | R18: 1 | S18: 0 | T18: 1 | U18: 0 | V18: 2 | W18: =IF(OR(ISBLANK(D18),W$169="N"),0,(W$170-D18)*W$168) -> 0 | X18: =IF(OR(ISBLANK(E18),X$169="N"),0,(X$170-E18)*X$168) -> 2.16 | Y18: =IF(OR(ISBLANK(F18),Y$169="N"),0,(Y$170-F18)*Y$168) -> 1.6 | Z18: =IF(OR(ISBLANK(G18),Z$169="N"),0,G18*Z$168) -> 1.2 | AA18: =IF(OR(ISBLANK(H18),AA$169="N"),0,H18*AA$168) -> 3 | AB18: =IF(OR(ISBLANK(I18),AB$169="N"),0,I18*AB$168) -> 5.9766667 | AC18: =IF(OR(ISBLANK(J18),AC$169="N"),0,J18*AC$168) -> 1 | AD18: =IF(OR(ISBLANK(L18),AD$169="N"),0,L18*AD$168) -> 2 | AE18: =IF(OR(ISBLANK(M18),AE$169="N"),0,M18*AE$168) -> 0 | AF18: =IF(OR(ISBLANK(N18),AF$169="N"),0,N18*AF$168) -> 1 | AG18: =IF(OR(ISBLANK(O18),AG$169="N"),0,O18*AG$168) -> 0 | AH18: =IF(OR(ISBLANK(P18),AH$169="N"),0,P18*AH$168) -> 1 | AI18: =IF(OR(ISBLANK(Q18),AI$169="N"),0,Q18*AI$168) -> 1 | AJ18: =IF(OR(ISBLANK(R18),AJ$169="N"),0,R18*AJ$168) -> 1 | AK18: =IF(OR(ISBLANK(S18),AK$169="N"),0,S18*AK$168) -> 0 | ... AN18: =IF(OR(ISBLANK(V18),AN$169="N"),0,V18*AN$168) -> 4 | AO18: =ROUND(SUM(W18:AN18),1) -> 25.4 | AP18: =ROUND(SUM(X18:AN18),1) -> 25.4
A19: Brooks Automation | B19: PreciseFlex 3400 | C19: USA | E19: 20 | F19: 0.09 | G19: 3 | H19: 4 | I19: 587.76 | J19: 1 | K19: propr, mult | L19: {=INDEX(DataValidation!$B$2:$B$11, _xlfn.XMATCH(K19, DataValidation!$A$2:$A$11))} -> 2 | M19: 0 | N19: 1 | O19: 0 | P19: 1 | Q19: 1 | R19: 1 | S19: 0 | T19: 1 | U19: 0 | V19: 2 | W19: =IF(OR(ISBLANK(D19),W$169="N"),0,(W$170-D19)*W$168) -> 0 | X19: =IF(OR(ISBLANK(E19),X$169="N"),0,(X$170-E19)*X$168) -> 3.2 | Y19: =IF(OR(ISBLANK(F19),Y$169="N"),0,(Y$170-F19)*Y$168) -> 0.2 | Z19: =IF(OR(ISBLANK(G19),Z$169="N"),0,G19*Z$168) -> 0.6 | AA19: =IF(OR(ISBLANK(H19),AA$169="N"),0,H19*AA$168) -> 2 | AB19: =IF(OR(ISBLANK(I19),AB$169="N"),0,I19*AB$168) -> 1.9592 | AC19: =IF(OR(ISBLANK(J19),AC$169="N"),0,J19*AC$168) -> 1 | AD19: =IF(OR(ISBLANK(L19),AD$169="N"),0,L19*AD$168) -> 2 | AE19: =IF(OR(ISBLANK(M19),AE$169="N"),0,M19*AE$168) -> 0 | AF19: =IF(OR(ISBLANK(N19),AF$169="N"),0,N19*AF$168) -> 1 | AG19: =IF(OR(ISBLANK(O19),AG$169="N"),0,O19*AG$168) -> 0 | AH19: =IF(OR(ISBLANK(P19),AH$169="N"),0,P19*AH$168) -> 1 | AI19: =IF(OR(ISBLANK(Q19),AI$169="N"),0,Q19*AI$168) -> 1 | AJ19: =IF(OR(ISBLANK(R19),AJ$169="N"),0,R19*AJ$168) -> 1 | AK19: =IF(OR(ISBLANK(S19),AK$169="N"),0,S19*AK$168) -> 0 | ... AN19: =IF(OR(ISBLANK(V19),AN$169="N"),0,V19*AN$168) -> 4 | AO19: =ROUND(SUM(W19:AN19),1) -> 19.5 | AP19: =ROUND(SUM(X19:AN19),1) -> 19.5
A20: Comau | B20: Aura | C20: Italy | E20: 1615 | F20: 0.1 | G20: 170 | H20: 6 | I20: 2790 | J20: 1 | K20: propr | L20: {=INDEX(DataValidation!$B$2:$B$11, _xlfn.XMATCH(K20, DataValidation!$A$2:$A$11))} -> 1 | M20: 0 | N20: 1 | O20: 0 | P20: 0 | Q20: 1 | R20: 0 | S20: 0 | T20: 0 | U20: 0 | V20: 1.5 | W20: =IF(OR(ISBLANK(D20),W$169="N"),0,(W$170-D20)*W$168) -> 0 | X20: =IF(OR(ISBLANK(E20),X$169="N"),0,(X$170-E20)*X$168) -> -60.6 | Y20: =IF(OR(ISBLANK(F20),Y$169="N"),0,(Y$170-F20)*Y$168) -> 0 | Z20: =IF(OR(ISBLANK(G20),Z$169="N"),0,G20*Z$168) -> 34 | AA20: =IF(OR(ISBLANK(H20),AA$169="N"),0,H20*AA$168) -> 3 | AB20: =IF(OR(ISBLANK(I20),AB$169="N"),0,I20*AB$168) -> 9.3 | AC20: =IF(OR(ISBLANK(J20),AC$169="N"),0,J20*AC$168) -> 1 | AD20: =IF(OR(ISBLANK(L20),AD$169="N"),0,L20*AD$168) -> 1 | AE20: =IF(OR(ISBLANK(M20),AE$169="N"),0,M20*AE$168) -> 0 | AF20: =IF(OR(ISBLANK(N20),AF$169="N"),0,N20*AF$168) -> 1 | AG20: =IF(OR(ISBLANK(O20),AG$169="N"),0,O20*AG$168) -> 0 | AH20: =IF(OR(ISBLANK(P20),AH$169="N"),0,P20*AH$168) -> 0 | AI20: =IF(OR(ISBLANK(Q20),AI$169="N"),0,Q20*AI$168) -> 1 | AJ20: =IF(OR(ISBLANK(R20),AJ$169="N"),0,R20*AJ$168) -> 0 | AK20: =IF(OR(ISBLANK(S20),AK$169="N"),0,S20*AK$168) -> 0 | ... AN20: =IF(OR(ISBLANK(V20),AN$169="N"),0,V20*AN$168) -> 3 | AO20: =ROUND(SUM(W20:AN20),1) -> -7.3 | AP20: =ROUND(SUM(X20:AN20),1) -> -7.3
A21: Comau | B21: Racer-5 | C21: Italy | E21: 34 | F21: 0.03 | G21: 5 | H21: 6 | I21: 809 | J21: 1 | K21: propr | L21: {=INDEX(DataValidation!$B$2:$B$11, _xlfn.XMATCH(K21, DataValidation!$A$2:$A$11))} -> 1 | M21: 0 | N21: 1 | P21: 1 | Q21: 1 | R21: 0 | S21: 0 | T21: 0 | U21: 0 | V21: 2 | W21: =IF(OR(ISBLANK(D21),W$169="N"),0,(W$170-D21)*W$168) -> 0 | X21: =IF(OR(ISBLANK(E21),X$169="N"),0,(X$170-E21)*X$168) -> 2.64 | Y21: =IF(OR(ISBLANK(F21),Y$169="N"),0,(Y$170-F21)*Y$168) -> 1.4 | Z21: =IF(OR(ISBLANK(G21),Z$169="N"),0,G21*Z$168) -> 1 | AA21: =IF(OR(ISBLANK(H21),AA$169="N"),0,H21*AA$168) -> 3 | AB21: =IF(OR(ISBLANK(I21),AB$169="N"),0,I21*AB$168) -> 2.6966667 | AC21: =IF(OR(ISBLANK(J21),AC$169="N"),0,J21*AC$168) -> 1 | AD21: =IF(OR(ISBLANK(L21),AD$169="N"),0,L21*AD$168) -> 1 | AE21: =IF(OR(ISBLANK(M21),AE$169="N"),0,M21*AE$168) -> 0 | AF21: =IF(OR(ISBLANK(N21),AF$169="N"),0,N21*AF$168) -> 1 | AG21: =IF(OR(ISBLANK(O21),AG$169="N"),0,O21*AG$168) -> 0 | AH21: =IF(OR(ISBLANK(P21),AH$169="N"),0,P21*AH$168) -> 1 | AI21: =IF(OR(ISBLANK(Q21),AI$169="N"),0,Q21*AI$168) -> 1 | AJ21: =IF(OR(ISBLANK(R21),AJ$169="N"),0,R21*AJ$168) -> 0 | AK21: =IF(OR(ISBLANK(S21),AK$169="N"),0,S21*AK$168) -> 0 | ... AN21: =IF(OR(ISBLANK(V21),AN$169="N"),0,V21*AN$168) -> 4 | AO21: =ROUND(SUM(W21:AN21),1) -> 19.7 | AP21: =ROUND(SUM(X21:AN21),1) -> 19.7
A22: Delta Electronics | B22: Delta D-Bot DC06 | C22: Taiwan | D22: 26900 | E22: 24 | F22: 0.02 | G22: 6 | H22: 6 | I22: 800 | J22: 1 | K22: propr, mult | L22: {=INDEX(DataValidation!$B$2:$B$11, _xlfn.XMATCH(K22, DataValidation!$A$2:$A$11))} -> 2 | M22: 0 | N22: 1 | O22: 1 | P22: 1 | Q22: 1 | R22: 1 | S22: 0 | T22: 0 | U22: 0 | V22: 2 | W22: =IF(OR(ISBLANK(D22),W$169="N"),0,(W$170-D22)*W$168) -> 3.08 | X22: =IF(OR(ISBLANK(E22),X$169="N"),0,(X$170-E22)*X$168) -> 3.04 | Y22: =IF(OR(ISBLANK(F22),Y$169="N"),0,(Y$170-F22)*Y$168) -> 1.6 | Z22: =IF(OR(ISBLANK(G22),Z$169="N"),0,G22*Z$168) -> 1.2 | AA22: =IF(OR(ISBLANK(H22),AA$169="N"),0,H22*AA$168) -> 3 | AB22: =IF(OR(ISBLANK(I22),AB$169="N"),0,I22*AB$168) -> 2.6666667 | AC22: =IF(OR(ISBLANK(J22),AC$169="N"),0,J22*AC$168) -> 1 | AD22: =IF(OR(ISBLANK(L22),AD$169="N"),0,L22*AD$168) -> 2 | AE22: =IF(OR(ISBLANK(M22),AE$169="N"),0,M22*AE$168) -> 0 | AF22: =IF(OR(ISBLANK(N22),AF$169="N"),0,N22*AF$168) -> 1 | AG22: =IF(OR(ISBLANK(O22),AG$169="N"),0,O22*AG$168) -> 1 | AH22: =IF(OR(ISBLANK(P22),AH$169="N"),0,P22*AH$168) -> 1 | AI22: =IF(OR(ISBLANK(Q22),AI$169="N"),0,Q22*AI$168) -> 1 | AJ22: =IF(OR(ISBLANK(R22),AJ$169="N"),0,R22*AJ$168) -> 1 | AK22: =IF(OR(ISBLANK(S22),AK$169="N"),0,S22*AK$168) -> 0 | ... AN22: =IF(OR(ISBLANK(V22),AN$169="N"),0,V22*AN$168) -> 4 | AO22: =ROUND(SUM(W22:AN22),1) -> 26.6 | AP22: =ROUND(SUM(X22:AN22),1) -> 23.5
A23: Delta Electronics | B23: Delta D-Bot DC08 | C23: Taiwan | D23: 31900 | E23: 40 | F23: 0.02 | G23: 8 | H23: 6 | I23: 1300 | J23: 1 | K23: propr, mult | L23: {=INDEX(DataValidation!$B$2:$B$11, _xlfn.XMATCH(K23, DataValidation!$A$2:$A$11))} -> 2 | M23: 0 | N23: 1 | O23: 1 | P23: 1 | Q23: 1 | R23: 1 | S23: 0 | T23: 0 | U23: 0 | V23: 2 | W23: =IF(OR(ISBLANK(D23),W$169="N"),0,(W$170-D23)*W$168) -> 2.4133333 | X23: =IF(OR(ISBLANK(E23),X$169="N"),0,(X$170-E23)*X$168) -> 2.4 | Y23: =IF(OR(ISBLANK(F23),Y$169="N"),0,(Y$170-F23)*Y$168) -> 1.6 | Z23: =IF(OR(ISBLANK(G23),Z$169="N"),0,G23*Z$168) -> 1.6 | AA23: =IF(OR(ISBLANK(H23),AA$169="N"),0,H23*AA$168) -> 3 | AB23: =IF(OR(ISBLANK(I23),AB$169="N"),0,I23*AB$168) -> 4.3333333 | AC23: =IF(OR(ISBLANK(J23),AC$169="N"),0,J23*AC$168) -> 1 | AD23: =IF(OR(ISBLANK(L23),AD$169="N"),0,L23*AD$168) -> 2 | AE23: =IF(OR(ISBLANK(M23),AE$169="N"),0,M23*AE$168) -> 0 | AF23: =IF(OR(ISBLANK(N23),AF$169="N"),0,N23*AF$168) -> 1 | AG23: =IF(OR(ISBLANK(O23),AG$169="N"),0,O23*AG$168) -> 1 | AH23: =IF(OR(ISBLANK(P23),AH$169="N"),0,P23*AH$168) -> 1 | AI23: =IF(OR(ISBLANK(Q23),AI$169="N"),0,Q23*AI$168) -> 1 | AJ23: =IF(OR(ISBLANK(R23),AJ$169="N"),0,R23*AJ$168) -> 1 | AK23: =IF(OR(ISBLANK(S23),AK$169="N"),0,S23*AK$168) -> 0 | ... AN23: =IF(OR(ISBLANK(V23),AN$169="N"),0,V23*AN$168) -> 4 | AO23: =ROUND(SUM(W23:AN23),1) -> 27.3 | AP23: =ROUND(SUM(X23:AN23),1) -> 24.9
A24: Delta Electronics | B24: Delta D-Bot DC10 | C24: Taiwan | D24: 33900 | E24: 39 | F24: 0.02 | G24: 10 | H24: 6 | I24: 1200 | J24: 1 | K24: propr, mult | L24: {=INDEX(DataValidation!$B$2:$B$11, _xlfn.XMATCH(K24, DataValidation!$A$2:$A$11))} -> 2 | M24: 0 | N24: 1 | O24: 1 | P24: 1 | Q24: 1 | R24: 1 | S24: 0 | T24: 0 | U24: 0 | V24: 2 | W24: =IF(OR(ISBLANK(D24),W$169="N"),0,(W$170-D24)*W$168) -> 2.1466667 | X24: =IF(OR(ISBLANK(E24),X$169="N"),0,(X$170-E24)*X$168) -> 2.44 | Y24: =IF(OR(ISBLANK(F24),Y$169="N"),0,(Y$170-F24)*Y$168) -> 1.6 | Z24: =IF(OR(ISBLANK(G24),Z$169="N"),0,G24*Z$168) -> 2 | AA24: =IF(OR(ISBLANK(H24),AA$169="N"),0,H24*AA$168) -> 3 | AB24: =IF(OR(ISBLANK(I24),AB$169="N"),0,I24*AB$168) -> 4 | AC24: =IF(OR(ISBLANK(J24),AC$169="N"),0,J24*AC$168) -> 1 | AD24: =IF(OR(ISBLANK(L24),AD$169="N"),0,L24*AD$168) -> 2 | AE24: =IF(OR(ISBLANK(M24),AE$169="N"),0,M24*AE$168) -> 0 | AF24: =IF(OR(ISBLANK(N24),AF$169="N"),0,N24*AF$168) -> 1 | AG24: =IF(OR(ISBLANK(O24),AG$169="N"),0,O24*AG$168) -> 1 | AH24: =IF(OR(ISBLANK(P24),AH$169="N"),0,P24*AH$168) -> 1 | AI24: =IF(OR(ISBLANK(Q24),AI$169="N"),0,Q24*AI$168) -> 1 | AJ24: =IF(OR(ISBLANK(R24),AJ$169="N"),0,R24*AJ$168) -> 1 | AK24: =IF(OR(ISBLANK(S24),AK$169="N"),0,S24*AK$168) -> 0 | ... AN24: =IF(OR(ISBLANK(V24),AN$169="N"),0,V24*AN$168) -> 4 | AO24: =ROUND(SUM(W24:AN24),1) -> 27.2 | AP24: =ROUND(SUM(X24:AN24),1) -> 25
A25: Delta Electronics | B25: Delta D-Bot DC16 | C25: Taiwan | D25: 38900 | E25: 70 | F25: 0.02 | G25: 16 | H25: 6 | I25: 1600 | J25: 1 | K25: propr, mult | L25: {=INDEX(DataValidation!$B$2:$B$11, _xlfn.XMATCH(K25, DataValidation!$A$2:$A$11))} -> 2 | M25: 0 | N25: 1 | O25: 1 | P25: 1 | Q25: 1 | R25: 1 | S25: 0 | T25: 0 | U25: 0 | V25: 2 | W25: =IF(OR(ISBLANK(D25),W$169="N"),0,(W$170-D25)*W$168) -> 1.48 | X25: =IF(OR(ISBLANK(E25),X$169="N"),0,(X$170-E25)*X$168) -> 1.2 | Y25: =IF(OR(ISBLANK(F25),Y$169="N"),0,(Y$170-F25)*Y$168) -> 1.6 | Z25: =IF(OR(ISBLANK(G25),Z$169="N"),0,G25*Z$168) -> 3.2 | AA25: =IF(OR(ISBLANK(H25),AA$169="N"),0,H25*AA$168) -> 3 | AB25: =IF(OR(ISBLANK(I25),AB$169="N"),0,I25*AB$168) -> 5.3333333 | AC25: =IF(OR(ISBLANK(J25),AC$169="N"),0,J25*AC$168) -> 1 | AD25: =IF(OR(ISBLANK(L25),AD$169="N"),0,L25*AD$168) -> 2 | AE25: =IF(OR(ISBLANK(M25),AE$169="N"),0,M25*AE$168) -> 0 | AF25: =IF(OR(ISBLANK(N25),AF$169="N"),0,N25*AF$168) -> 1 | AG25: =IF(OR(ISBLANK(O25),AG$169="N"),0,O25*AG$168) -> 1 | AH25: =IF(OR(ISBLANK(P25),AH$169="N"),0,P25*AH$168) -> 1 | AI25: =IF(OR(ISBLANK(Q25),AI$169="N"),0,Q25*AI$168) -> 1 | AJ25: =IF(OR(ISBLANK(R25),AJ$169="N"),0,R25*AJ$168) -> 1 | AK25: =IF(OR(ISBLANK(S25),AK$169="N"),0,S25*AK$168) -> 0 | ... AN25: =IF(OR(ISBLANK(V25),AN$169="N"),0,V25*AN$168) -> 4 | AO25: =ROUND(SUM(W25:AN25),1) -> 27.8 | AP25: =ROUND(SUM(X25:AN25),1) -> 26.3
A26: Delta Electronics | B26: Delta D-Bot DC20 | C26: Taiwan | D26: 47900 | E26: 101 | F26: 0.02 | G26: 20 | H26: 6 | I26: 1800 | J26: 1 | K26: propr, mult | L26: {=INDEX(DataValidation!$B$2:$B$11, _xlfn.XMATCH(K26, DataValidation!$A$2:$A$11))} -> 2 | M26: 0 | N26: 1 | O26: 1 | P26: 1 | Q26: 1 | R26: 1 | S26: 0 | T26: 0 | U26: 0 | V26: 2 | W26: =IF(OR(ISBLANK(D26),W$169="N"),0,(W$170-D26)*W$168) -> 0.28 | X26: =IF(OR(ISBLANK(E26),X$169="N"),0,(X$170-E26)*X$168) -> -0.04 | Y26: =IF(OR(ISBLANK(F26),Y$169="N"),0,(Y$170-F26)*Y$168) -> 1.6 | Z26: =IF(OR(ISBLANK(G26),Z$169="N"),0,G26*Z$168) -> 4 | AA26: =IF(OR(ISBLANK(H26),AA$169="N"),0,H26*AA$168) -> 3 | AB26: =IF(OR(ISBLANK(I26),AB$169="N"),0,I26*AB$168) -> 6 | AC26: =IF(OR(ISBLANK(J26),AC$169="N"),0,J26*AC$168) -> 1 | AD26: =IF(OR(ISBLANK(L26),AD$169="N"),0,L26*AD$168) -> 2 | AE26: =IF(OR(ISBLANK(M26),AE$169="N"),0,M26*AE$168) -> 0 | AF26: =IF(OR(ISBLANK(N26),AF$169="N"),0,N26*AF$168) -> 1 | AG26: =IF(OR(ISBLANK(O26),AG$169="N"),0,O26*AG$168) -> 1 | AH26: =IF(OR(ISBLANK(P26),AH$169="N"),0,P26*AH$168) -> 1 | AI26: =IF(OR(ISBLANK(Q26),AI$169="N"),0,Q26*AI$168) -> 1 | AJ26: =IF(OR(ISBLANK(R26),AJ$169="N"),0,R26*AJ$168) -> 1 | AK26: =IF(OR(ISBLANK(S26),AK$169="N"),0,S26*AK$168) -> 0 | ... AN26: =IF(OR(ISBLANK(V26),AN$169="N"),0,V26*AN$168) -> 4 | AO26: =ROUND(SUM(W26:AN26),1) -> 26.8 | AP26: =ROUND(SUM(X26:AN26),1) -> 26.6
A27: Delta Electronics | B27: Delta D-Bot DC30 | C27: Taiwan | D27: 52900 | E27: 98 | F27: 0.02 | G27: 30 | H27: 6 | I27: 1300 | J27: 1 | K27: propr, mult | L27: {=INDEX(DataValidation!$B$2:$B$11, _xlfn.XMATCH(K27, DataValidation!$A$2:$A$11))} -> 2 | M27: 0 | N27: 1 | O27: 1 | P27: 1 | Q27: 1 | R27: 1 | S27: 0 | T27: 0 | U27: 0 | V27: 2 | W27: =IF(OR(ISBLANK(D27),W$169="N"),0,(W$170-D27)*W$168) -> -0.38666667 | X27: =IF(OR(ISBLANK(E27),X$169="N"),0,(X$170-E27)*X$168) -> 0.08 | Y27: =IF(OR(ISBLANK(F27),Y$169="N"),0,(Y$170-F27)*Y$168) -> 1.6 | Z27: =IF(OR(ISBLANK(G27),Z$169="N"),0,G27*Z$168) -> 6 | AA27: =IF(OR(ISBLANK(H27),AA$169="N"),0,H27*AA$168) -> 3 | AB27: =IF(OR(ISBLANK(I27),AB$169="N"),0,I27*AB$168) -> 4.3333333 | AC27: =IF(OR(ISBLANK(J27),AC$169="N"),0,J27*AC$168) -> 1 | AD27: =IF(OR(ISBLANK(L27),AD$169="N"),0,L27*AD$168) -> 2 | AE27: =IF(OR(ISBLANK(M27),AE$169="N"),0,M27*AE$168) -> 0 | AF27: =IF(OR(ISBLANK(N27),AF$169="N"),0,N27*AF$168) -> 1 | AG27: =IF(OR(ISBLANK(O27),AG$169="N"),0,O27*AG$168) -> 1 | AH27: =IF(OR(ISBLANK(P27),AH$169="N"),0,P27*AH$168) -> 1 | AI27: =IF(OR(ISBLANK(Q27),AI$169="N"),0,Q27*AI$168) -> 1 | AJ27: =IF(OR(ISBLANK(R27),AJ$169="N"),0,R27*AJ$168) -> 1 | AK27: =IF(OR(ISBLANK(S27),AK$169="N"),0,S27*AK$168) -> 0 | ... AN27: =IF(OR(ISBLANK(V27),AN$169="N"),0,V27*AN$168) -> 4 | AO27: =ROUND(SUM(W27:AN27),1) -> 26.6 | AP27: =ROUND(SUM(X27:AN27),1) -> 27
A28: DENSO Robotocs | B28: COBOTTA | C28: Japan | D28: 14800 | E28: 4 | F28: 0.05 | G28: 0.5 | H28: 6 | I28: 343 | J28: 1 | K28: propr, open, mult | L28: {=INDEX(DataValidation!$B$2:$B$11, _xlfn.XMATCH(K28, DataValidation!$A$2:$A$11))} -> 3 | M28: 0 | N28: 1 | O28: 0 | P28: 1 | Q28: 1 | R28: 0 | S28: 0 | T28: 0 | U28: 0 | V28: 2 | W28: =IF(OR(ISBLANK(D28),W$169="N"),0,(W$170-D28)*W$168) -> 4.6933333 | X28: =IF(OR(ISBLANK(E28),X$169="N"),0,(X$170-E28)*X$168) -> 3.84 | Y28: =IF(OR(ISBLANK(F28),Y$169="N"),0,(Y$170-F28)*Y$168) -> 1 | Z28: =IF(OR(ISBLANK(G28),Z$169="N"),0,G28*Z$168) -> 0.1 | AA28: =IF(OR(ISBLANK(H28),AA$169="N"),0,H28*AA$168) -> 3 | AB28: =IF(OR(ISBLANK(I28),AB$169="N"),0,I28*AB$168) -> 1.1433333 | AC28: =IF(OR(ISBLANK(J28),AC$169="N"),0,J28*AC$168) -> 1 | AD28: =IF(OR(ISBLANK(L28),AD$169="N"),0,L28*AD$168) -> 3 | AE28: =IF(OR(ISBLANK(M28),AE$169="N"),0,M28*AE$168) -> 0 | AF28: =IF(OR(ISBLANK(N28),AF$169="N"),0,N28*AF$168) -> 1 | AG28: =IF(OR(ISBLANK(O28),AG$169="N"),0,O28*AG$168) -> 0 | AH28: =IF(OR(ISBLANK(P28),AH$169="N"),0,P28*AH$168) -> 1 | AI28: =IF(OR(ISBLANK(Q28),AI$169="N"),0,Q28*AI$168) -> 1 | AJ28: =IF(OR(ISBLANK(R28),AJ$169="N"),0,R28*AJ$168) -> 0 | AK28: =IF(OR(ISBLANK(S28),AK$169="N"),0,S28*AK$168) -> 0 | ... AN28: =IF(OR(ISBLANK(V28),AN$169="N"),0,V28*AN$168) -> 4 | AO28: =ROUND(SUM(W28:AN28),1) -> 24.8 | AP28: =ROUND(SUM(X28:AN28),1) -> 20.1
A29: DENSO Robotocs | B29: COBOTTA PRO 1300 | C29: Japan | E29: 12 | F29: 0.04 | G29: 12 | H29: 6 | I29: 1303 | J29: 1 | K29: propr, open, mult | L29: {=INDEX(DataValidation!$B$2:$B$11, _xlfn.XMATCH(K29, DataValidation!$A$2:$A$11))} -> 3 | M29: 0 | N29: 1 | O29: 0 | P29: 1 | Q29: 0 | R29: 0 | S29: 0 | T29: 1 | U29: 0 | V29: 2 | W29: =IF(OR(ISBLANK(D29),W$169="N"),0,(W$170-D29)*W$168) -> 0 | X29: =IF(OR(ISBLANK(E29),X$169="N"),0,(X$170-E29)*X$168) -> 3.52 | Y29: =IF(OR(ISBLANK(F29),Y$169="N"),0,(Y$170-F29)*Y$168) -> 1.2 | Z29: =IF(OR(ISBLANK(G29),Z$169="N"),0,G29*Z$168) -> 2.4 | AA29: =IF(OR(ISBLANK(H29),AA$169="N"),0,H29*AA$168) -> 3 | AB29: =IF(OR(ISBLANK(I29),AB$169="N"),0,I29*AB$168) -> 4.3433333 | AC29: =IF(OR(ISBLANK(J29),AC$169="N"),0,J29*AC$168) -> 1 | AD29: =IF(OR(ISBLANK(L29),AD$169="N"),0,L29*AD$168) -> 3 | AE29: =IF(OR(ISBLANK(M29),AE$169="N"),0,M29*AE$168) -> 0 | AF29: =IF(OR(ISBLANK(N29),AF$169="N"),0,N29*AF$168) -> 1 | AG29: =IF(OR(ISBLANK(O29),AG$169="N"),0,O29*AG$168) -> 0 | AH29: =IF(OR(ISBLANK(P29),AH$169="N"),0,P29*AH$168) -> 1 | AI29: =IF(OR(ISBLANK(Q29),AI$169="N"),0,Q29*AI$168) -> 0 | AJ29: =IF(OR(ISBLANK(R29),AJ$169="N"),0,R29*AJ$168) -> 0 | AK29: =IF(OR(ISBLANK(S29),AK$169="N"),0,S29*AK$168) -> 0 | ... AN29: =IF(OR(ISBLANK(V29),AN$169="N"),0,V29*AN$168) -> 4 | AO29: =ROUND(SUM(W29:AN29),1) -> 25 | AP29: =ROUND(SUM(X29:AN29),1) -> 25
A30: Dobot | B30: CR5 | C30: China | D30: 15390 | E30: 23 | F30: 0.03 | G30: 5 | H30: 6 | I30: 900 | J30: 1 | K30: propr, open, mult | L30: {=INDEX(DataValidation!$B$2:$B$11, _xlfn.XMATCH(K30, DataValidation!$A$2:$A$11))} -> 3 | M30: 0 | N30: 1 | O30: 1 | P30: 1 | Q30: 1 | R30: 0 | S30: 1 | T30: 0 | U30: 0 | V30: 2 | W30: =IF(OR(ISBLANK(D30),W$169="N"),0,(W$170-D30)*W$168) -> 4.6146667 | X30: =IF(OR(ISBLANK(E30),X$169="N"),0,(X$170-E30)*X$168) -> 3.08 | Y30: =IF(OR(ISBLANK(F30),Y$169="N"),0,(Y$170-F30)*Y$168) -> 1.4 | Z30: =IF(OR(ISBLANK(G30),Z$169="N"),0,G30*Z$168) -> 1 | AA30: =IF(OR(ISBLANK(H30),AA$169="N"),0,H30*AA$168) -> 3 | AB30: =IF(OR(ISBLANK(I30),AB$169="N"),0,I30*AB$168) -> 3 | AC30: =IF(OR(ISBLANK(J30),AC$169="N"),0,J30*AC$168) -> 1 | AD30: =IF(OR(ISBLANK(L30),AD$169="N"),0,L30*AD$168) -> 3 | AE30: =IF(OR(ISBLANK(M30),AE$169="N"),0,M30*AE$168) -> 0 | AF30: =IF(OR(ISBLANK(N30),AF$169="N"),0,N30*AF$168) -> 1 | AG30: =IF(OR(ISBLANK(O30),AG$169="N"),0,O30*AG$168) -> 1 | AH30: =IF(OR(ISBLANK(P30),AH$169="N"),0,P30*AH$168) -> 1 | AI30: =IF(OR(ISBLANK(Q30),AI$169="N"),0,Q30*AI$168) -> 1 | AJ30: =IF(OR(ISBLANK(R30),AJ$169="N"),0,R30*AJ$168) -> 0 | AK30: =IF(OR(ISBLANK(S30),AK$169="N"),0,S30*AK$168) -> 0.5 | ... AN30: =IF(OR(ISBLANK(V30),AN$169="N"),0,V30*AN$168) -> 4 | AO30: =ROUND(SUM(W30:AN30),1) -> 28.6 | AP30: =ROUND(SUM(X30:AN30),1) -> 24
A31: Dobot | B31: CR10 | C31: China | D31: 21540 | E31: 40 | F31: 0.03 | G31: 10 | H31: 6 | I31: 1300 | J31: 1 | K31: propr, open, mult | L31: {=INDEX(DataValidation!$B$2:$B$11, _xlfn.XMATCH(K31, DataValidation!$A$2:$A$11))} -> 3 | M31: 0 | N31: 1 | O31: 1 | P31: 1 | Q31: 1 | R31: 0 | S31: 1 | T31: 0 | U31: 0 | V31: 2 | W31: =IF(OR(ISBLANK(D31),W$169="N"),0,(W$170-D31)*W$168) -> 3.7946667 | X31: =IF(OR(ISBLANK(E31),X$169="N"),0,(X$170-E31)*X$168) -> 2.4 | Y31: =IF(OR(ISBLANK(F31),Y$169="N"),0,(Y$170-F31)*Y$168) -> 1.4 | Z31: =IF(OR(ISBLANK(G31),Z$169="N"),0,G31*Z$168) -> 2 | AA31: =IF(OR(ISBLANK(H31),AA$169="N"),0,H31*AA$168) -> 3 | AB31: =IF(OR(ISBLANK(I31),AB$169="N"),0,I31*AB$168) -> 4.3333333 | AC31: =IF(OR(ISBLANK(J31),AC$169="N"),0,J31*AC$168) -> 1 | AD31: =IF(OR(ISBLANK(L31),AD$169="N"),0,L31*AD$168) -> 3 | AE31: =IF(OR(ISBLANK(M31),AE$169="N"),0,M31*AE$168) -> 0 | AF31: =IF(OR(ISBLANK(N31),AF$169="N"),0,N31*AF$168) -> 1 | AG31: =IF(OR(ISBLANK(O31),AG$169="N"),0,O31*AG$168) -> 1 | AH31: =IF(OR(ISBLANK(P31),AH$169="N"),0,P31*AH$168) -> 1 | AI31: =IF(OR(ISBLANK(Q31),AI$169="N"),0,Q31*AI$168) -> 1 | AJ31: =IF(OR(ISBLANK(R31),AJ$169="N"),0,R31*AJ$168) -> 0 | AK31: =IF(OR(ISBLANK(S31),AK$169="N"),0,S31*AK$168) -> 0.5 | ... AN31: =IF(OR(ISBLANK(V31),AN$169="N"),0,V31*AN$168) -> 4 | AO31: =ROUND(SUM(W31:AN31),1) -> 29.4 | AP31: =ROUND(SUM(X31:AN31),1) -> 25.6
A32: Dobot | B32: Nova 2 | C32: China | D32: 8920 | E32: 11 | F32: 0.05 | G32: 2 | H32: 6 | I32: 625 | J32: 1 | K32: propr, open, mult | L32: {=INDEX(DataValidation!$B$2:$B$11, _xlfn.XMATCH(K32, DataValidation!$A$2:$A$11))} -> 3 | M32: 0 | N32: 0 | O32: 0 | P32: 0 | Q32: 0 | R32: 0 | S32: 1 | T32: 1 | U32: 0 | V32: 2 | W32: =IF(OR(ISBLANK(D32),W$169="N"),0,(W$170-D32)*W$168) -> 5.4773333 | X32: =IF(OR(ISBLANK(E32),X$169="N"),0,(X$170-E32)*X$168) -> 3.56 | Y32: =IF(OR(ISBLANK(F32),Y$169="N"),0,(Y$170-F32)*Y$168) -> 1 | Z32: =IF(OR(ISBLANK(G32),Z$169="N"),0,G32*Z$168) -> 0.4 | AA32: =IF(OR(ISBLANK(H32),AA$169="N"),0,H32*AA$168) -> 3 | AB32: =IF(OR(ISBLANK(I32),AB$169="N"),0,I32*AB$168) -> 2.0833333 | AC32: =IF(OR(ISBLANK(J32),AC$169="N"),0,J32*AC$168) -> 1 | AD32: =IF(OR(ISBLANK(L32),AD$169="N"),0,L32*AD$168) -> 3 | AE32: =IF(OR(ISBLANK(M32),AE$169="N"),0,M32*AE$168) -> 0 | AF32: =IF(OR(ISBLANK(N32),AF$169="N"),0,N32*AF$168) -> 0 | AG32: =IF(OR(ISBLANK(O32),AG$169="N"),0,O32*AG$168) -> 0 | AH32: =IF(OR(ISBLANK(P32),AH$169="N"),0,P32*AH$168) -> 0 | AI32: =IF(OR(ISBLANK(Q32),AI$169="N"),0,Q32*AI$168) -> 0 | AJ32: =IF(OR(ISBLANK(R32),AJ$169="N"),0,R32*AJ$168) -> 0 | AK32: =IF(OR(ISBLANK(S32),AK$169="N"),0,S32*AK$168) -> 0.5 | ... AN32: =IF(OR(ISBLANK(V32),AN$169="N"),0,V32*AN$168) -> 4 | AO32: =ROUND(SUM(W32:AN32),1) -> 24.5 | AP32: =ROUND(SUM(X32:AN32),1) -> 19
A33: Dobot | B33: Nova 5 | C33: China | D33: 9540 | E33: 14 | F33: 0.05 | G33: 5 | H33: 6 | I33: 850 | J33: 1 | K33: propr, open, mult | L33: {=INDEX(DataValidation!$B$2:$B$11, _xlfn.XMATCH(K33, DataValidation!$A$2:$A$11))} -> 3 | M33: 0 | N33: 0 | O33: 0 | P33: 0 | Q33: 0 | R33: 0 | S33: 1 | T33: 1 | U33: 0 | V33: 2 | W33: =IF(OR(ISBLANK(D33),W$169="N"),0,(W$170-D33)*W$168) -> 5.3946667 | X33: =IF(OR(ISBLANK(E33),X$169="N"),0,(X$170-E33)*X$168) -> 3.44 | Y33: =IF(OR(ISBLANK(F33),Y$169="N"),0,(Y$170-F33)*Y$168) -> 1 | Z33: =IF(OR(ISBLANK(G33),Z$169="N"),0,G33*Z$168) -> 1 | AA33: =IF(OR(ISBLANK(H33),AA$169="N"),0,H33*AA$168) -> 3 | AB33: =IF(OR(ISBLANK(I33),AB$169="N"),0,I33*AB$168) -> 2.8333333 | AC33: =IF(OR(ISBLANK(J33),AC$169="N"),0,J33*AC$168) -> 1 | AD33: =IF(OR(ISBLANK(L33),AD$169="N"),0,L33*AD$168) -> 3 | AE33: =IF(OR(ISBLANK(M33),AE$169="N"),0,M33*AE$168) -> 0 | AF33: =IF(OR(ISBLANK(N33),AF$169="N"),0,N33*AF$168) -> 0 | AG33: =IF(OR(ISBLANK(O33),AG$169="N"),0,O33*AG$168) -> 0 | AH33: =IF(OR(ISBLANK(P33),AH$169="N"),0,P33*AH$168) -> 0 | AI33: =IF(OR(ISBLANK(Q33),AI$169="N"),0,Q33*AI$168) -> 0 | AJ33: =IF(OR(ISBLANK(R33),AJ$169="N"),0,R33*AJ$168) -> 0 | AK33: =IF(OR(ISBLANK(S33),AK$169="N"),0,S33*AK$168) -> 0.5 | ... AN33: =IF(OR(ISBLANK(V33),AN$169="N"),0,V33*AN$168) -> 4 | AO33: =ROUND(SUM(W33:AN33),1) -> 25.7 | AP33: =ROUND(SUM(X33:AN33),1) -> 20.3
A34: Doosan Robotics | B34: A0509 | C34: South Korea | D34: 22500 | E34: 21 | F34: 0.03 | G34: 5 | H34: 6 | I34: 900 | J34: 1 | K34: propr | L34: {=INDEX(DataValidation!$B$2:$B$11, _xlfn.XMATCH(K34, DataValidation!$A$2:$A$11))} -> 1 | M34: 0 | N34: 1 | O34: 0 | P34: 1 | Q34: 1 | R34: 1 | S34: 0 | T34: 0 | U34: 0 | V34: 2 | W34: =IF(OR(ISBLANK(D34),W$169="N"),0,(W$170-D34)*W$168) -> 3.6666667 | X34: =IF(OR(ISBLANK(E34),X$169="N"),0,(X$170-E34)*X$168) -> 3.16 | Y34: =IF(OR(ISBLANK(F34),Y$169="N"),0,(Y$170-F34)*Y$168) -> 1.4 | Z34: =IF(OR(ISBLANK(G34),Z$169="N"),0,G34*Z$168) -> 1 | AA34: =IF(OR(ISBLANK(H34),AA$169="N"),0,H34*AA$168) -> 3 | AB34: =IF(OR(ISBLANK(I34),AB$169="N"),0,I34*AB$168) -> 3 | AC34: =IF(OR(ISBLANK(J34),AC$169="N"),0,J34*AC$168) -> 1 | AD34: =IF(OR(ISBLANK(L34),AD$169="N"),0,L34*AD$168) -> 1 | AE34: =IF(OR(ISBLANK(M34),AE$169="N"),0,M34*AE$168) -> 0 | AF34: =IF(OR(ISBLANK(N34),AF$169="N"),0,N34*AF$168) -> 1 | AG34: =IF(OR(ISBLANK(O34),AG$169="N"),0,O34*AG$168) -> 0 | AH34: =IF(OR(ISBLANK(P34),AH$169="N"),0,P34*AH$168) -> 1 | AI34: =IF(OR(ISBLANK(Q34),AI$169="N"),0,Q34*AI$168) -> 1 | AJ34: =IF(OR(ISBLANK(R34),AJ$169="N"),0,R34*AJ$168) -> 1 | AK34: =IF(OR(ISBLANK(S34),AK$169="N"),0,S34*AK$168) -> 0 | ... AN34: =IF(OR(ISBLANK(V34),AN$169="N"),0,V34*AN$168) -> 4 | AO34: =ROUND(SUM(W34:AN34),1) -> 25.2 | AP34: =ROUND(SUM(X34:AN34),1) -> 21.6
A35: Doosan Robotics | B35: A0912 | C35: South Korea | D35: 27500 | E35: 27 | F35: 0.05 | G35: 9 | H35: 6 | I35: 1200 | J35: 1 | K35: propr | L35: {=INDEX(DataValidation!$B$2:$B$11, _xlfn.XMATCH(K35, DataValidation!$A$2:$A$11))} -> 1 | M35: 0 | N35: 1 | O35: 0 | P35: 1 | Q35: 1 | R35: 1 | S35: 0 | T35: 0 | U35: 0 | V35: 2 | W35: =IF(OR(ISBLANK(D35),W$169="N"),0,(W$170-D35)*W$168) -> 3 | X35: =IF(OR(ISBLANK(E35),X$169="N"),0,(X$170-E35)*X$168) -> 2.92 | Y35: =IF(OR(ISBLANK(F35),Y$169="N"),0,(Y$170-F35)*Y$168) -> 1 | Z35: =IF(OR(ISBLANK(G35),Z$169="N"),0,G35*Z$168) -> 1.8 | AA35: =IF(OR(ISBLANK(H35),AA$169="N"),0,H35*AA$168) -> 3 | AB35: =IF(OR(ISBLANK(I35),AB$169="N"),0,I35*AB$168) -> 4 | AC35: =IF(OR(ISBLANK(J35),AC$169="N"),0,J35*AC$168) -> 1 | AD35: =IF(OR(ISBLANK(L35),AD$169="N"),0,L35*AD$168) -> 1 | AE35: =IF(OR(ISBLANK(M35),AE$169="N"),0,M35*AE$168) -> 0 | AF35: =IF(OR(ISBLANK(N35),AF$169="N"),0,N35*AF$168) -> 1 | AG35: =IF(OR(ISBLANK(O35),AG$169="N"),0,O35*AG$168) -> 0 | AH35: =IF(OR(ISBLANK(P35),AH$169="N"),0,P35*AH$168) -> 1 | AI35: =IF(OR(ISBLANK(Q35),AI$169="N"),0,Q35*AI$168) -> 1 | AJ35: =IF(OR(ISBLANK(R35),AJ$169="N"),0,R35*AJ$168) -> 1 | AK35: =IF(OR(ISBLANK(S35),AK$169="N"),0,S35*AK$168) -> 0 | ... AN35: =IF(OR(ISBLANK(V35),AN$169="N"),0,V35*AN$168) -> 4 | AO35: =ROUND(SUM(W35:AN35),1) -> 25.7 | AP35: =ROUND(SUM(X35:AN35),1) -> 22.7
A36: Doosan Robotics | B36: M0609 | C36: South Korea | D36: 29500 | E36: 27 | F36: 0.05 | G36: 6 | H36: 6 | I36: 900 | J36: 1 | K36: propr | L36: {=INDEX(DataValidation!$B$2:$B$11, _xlfn.XMATCH(K36, DataValidation!$A$2:$A$11))} -> 1 | M36: 1 | N36: 1 | O36: 1 | P36: 1 | Q36: 1 | R36: 0 | S36: 0 | T36: 0 | U36: 0 | V36: 2 | W36: =IF(OR(ISBLANK(D36),W$169="N"),0,(W$170-D36)*W$168) -> 2.7333333 | X36: =IF(OR(ISBLANK(E36),X$169="N"),0,(X$170-E36)*X$168) -> 2.92 | Y36: =IF(OR(ISBLANK(F36),Y$169="N"),0,(Y$170-F36)*Y$168) -> 1 | Z36: =IF(OR(ISBLANK(G36),Z$169="N"),0,G36*Z$168) -> 1.2 | AA36: =IF(OR(ISBLANK(H36),AA$169="N"),0,H36*AA$168) -> 3 | AB36: =IF(OR(ISBLANK(I36),AB$169="N"),0,I36*AB$168) -> 3 | AC36: =IF(OR(ISBLANK(J36),AC$169="N"),0,J36*AC$168) -> 1 | AD36: =IF(OR(ISBLANK(L36),AD$169="N"),0,L36*AD$168) -> 1 | AE36: =IF(OR(ISBLANK(M36),AE$169="N"),0,M36*AE$168) -> 1 | AF36: =IF(OR(ISBLANK(N36),AF$169="N"),0,N36*AF$168) -> 1 | AG36: =IF(OR(ISBLANK(O36),AG$169="N"),0,O36*AG$168) -> 1 | AH36: =IF(OR(ISBLANK(P36),AH$169="N"),0,P36*AH$168) -> 1 | AI36: =IF(OR(ISBLANK(Q36),AI$169="N"),0,Q36*AI$168) -> 1 | AJ36: =IF(OR(ISBLANK(R36),AJ$169="N"),0,R36*AJ$168) -> 0 | AK36: =IF(OR(ISBLANK(S36),AK$169="N"),0,S36*AK$168) -> 0 | ... AN36: =IF(OR(ISBLANK(V36),AN$169="N"),0,V36*AN$168) -> 4 | AO36: =ROUND(SUM(W36:AN36),1) -> 24.9 | AP36: =ROUND(SUM(X36:AN36),1) -> 22.1
A37: Doosan Robotics | B37: M1509 | C37: South Korea | D37: 37500 | E37: 32 | F37: 0.05 | G37: 15 | H37: 6 | I37: 900 | J37: 1 | K37: propr | L37: {=INDEX(DataValidation!$B$2:$B$11, _xlfn.XMATCH(K37, DataValidation!$A$2:$A$11))} -> 1 | M37: 1 | N37: 1 | O37: 1 | P37: 1 | Q37: 1 | R37: 0 | S37: 0 | T37: 0 | U37: 0 | V37: 2 | W37: =IF(OR(ISBLANK(D37),W$169="N"),0,(W$170-D37)*W$168) -> 1.6666667 | X37: =IF(OR(ISBLANK(E37),X$169="N"),0,(X$170-E37)*X$168) -> 2.72 | Y37: =IF(OR(ISBLANK(F37),Y$169="N"),0,(Y$170-F37)*Y$168) -> 1 | Z37: =IF(OR(ISBLANK(G37),Z$169="N"),0,G37*Z$168) -> 3 | AA37: =IF(OR(ISBLANK(H37),AA$169="N"),0,H37*AA$168) -> 3 | AB37: =IF(OR(ISBLANK(I37),AB$169="N"),0,I37*AB$168) -> 3 | AC37: =IF(OR(ISBLANK(J37),AC$169="N"),0,J37*AC$168) -> 1 | AD37: =IF(OR(ISBLANK(L37),AD$169="N"),0,L37*AD$168) -> 1 | AE37: =IF(OR(ISBLANK(M37),AE$169="N"),0,M37*AE$168) -> 1 | AF37: =IF(OR(ISBLANK(N37),AF$169="N"),0,N37*AF$168) -> 1 | AG37: =IF(OR(ISBLANK(O37),AG$169="N"),0,O37*AG$168) -> 1 | AH37: =IF(OR(ISBLANK(P37),AH$169="N"),0,P37*AH$168) -> 1 | AI37: =IF(OR(ISBLANK(Q37),AI$169="N"),0,Q37*AI$168) -> 1 | AJ37: =IF(OR(ISBLANK(R37),AJ$169="N"),0,R37*AJ$168) -> 0 | AK37: =IF(OR(ISBLANK(S37),AK$169="N"),0,S37*AK$168) -> 0 | ... AN37: =IF(OR(ISBLANK(V37),AN$169="N"),0,V37*AN$168) -> 4 | AO37: =ROUND(SUM(W37:AN37),1) -> 25.4 | AP37: =ROUND(SUM(X37:AN37),1) -> 23.7
A38: Doosan Robotics | B38: H2017 | C38: South Korea | D38: 44000 | E38: 74 | F38: 0.1 | G38: 20 | H38: 6 | I38: 1700 | J38: 1 | K38: propr | L38: {=INDEX(DataValidation!$B$2:$B$11, _xlfn.XMATCH(K38, DataValidation!$A$2:$A$11))} -> 1 | M38: 1 | N38: 1 | O38: 0 | P38: 1 | Q38: 1 | R38: 1 | S38: 0 | T38: 0 | U38: 0 | V38: 2 | W38: =IF(OR(ISBLANK(D38),W$169="N"),0,(W$170-D38)*W$168) -> 0.8 | X38: =IF(OR(ISBLANK(E38),X$169="N"),0,(X$170-E38)*X$168) -> 1.04 | Y38: =IF(OR(ISBLANK(F38),Y$169="N"),0,(Y$170-F38)*Y$168) -> 0 | Z38: =IF(OR(ISBLANK(G38),Z$169="N"),0,G38*Z$168) -> 4 | AA38: =IF(OR(ISBLANK(H38),AA$169="N"),0,H38*AA$168) -> 3 | AB38: =IF(OR(ISBLANK(I38),AB$169="N"),0,I38*AB$168) -> 5.6666667 | AC38: =IF(OR(ISBLANK(J38),AC$169="N"),0,J38*AC$168) -> 1 | AD38: =IF(OR(ISBLANK(L38),AD$169="N"),0,L38*AD$168) -> 1 | AE38: =IF(OR(ISBLANK(M38),AE$169="N"),0,M38*AE$168) -> 1 | AF38: =IF(OR(ISBLANK(N38),AF$169="N"),0,N38*AF$168) -> 1 | AG38: =IF(OR(ISBLANK(O38),AG$169="N"),0,O38*AG$168) -> 0 | AH38: =IF(OR(ISBLANK(P38),AH$169="N"),0,P38*AH$168) -> 1 | AI38: =IF(OR(ISBLANK(Q38),AI$169="N"),0,Q38*AI$168) -> 1 | AJ38: =IF(OR(ISBLANK(R38),AJ$169="N"),0,R38*AJ$168) -> 1 | AK38: =IF(OR(ISBLANK(S38),AK$169="N"),0,S38*AK$168) -> 0 | ... AN38: =IF(OR(ISBLANK(V38),AN$169="N"),0,V38*AN$168) -> 4 | AO38: =ROUND(SUM(W38:AN38),1) -> 25.5 | AP38: =ROUND(SUM(X38:AN38),1) -> 24.7
A39: Doosan Robotics | B39: H2515 | C39: South Korea | D39: 50500 | E39: 72 | F39: 0.1 | G39: 25 | H39: 6 | I39: 1500 | J39: 1 | K39: propr | L39: {=INDEX(DataValidation!$B$2:$B$11, _xlfn.XMATCH(K39, DataValidation!$A$2:$A$11))} -> 1 | M39: 1 | N39: 1 | O39: 0 | P39: 1 | Q39: 1 | R39: 1 | S39: 0 | T39: 0 | U39: 0 | V39: 2 | W39: =IF(OR(ISBLANK(D39),W$169="N"),0,(W$170-D39)*W$168) -> -0.066666667 | X39: =IF(OR(ISBLANK(E39),X$169="N"),0,(X$170-E39)*X$168) -> 1.12 | Y39: =IF(OR(ISBLANK(F39),Y$169="N"),0,(Y$170-F39)*Y$168) -> 0 | Z39: =IF(OR(ISBLANK(G39),Z$169="N"),0,G39*Z$168) -> 5 | AA39: =IF(OR(ISBLANK(H39),AA$169="N"),0,H39*AA$168) -> 3 | AB39: =IF(OR(ISBLANK(I39),AB$169="N"),0,I39*AB$168) -> 5 | AC39: =IF(OR(ISBLANK(J39),AC$169="N"),0,J39*AC$168) -> 1 | AD39: =IF(OR(ISBLANK(L39),AD$169="N"),0,L39*AD$168) -> 1 | AE39: =IF(OR(ISBLANK(M39),AE$169="N"),0,M39*AE$168) -> 1 | AF39: =IF(OR(ISBLANK(N39),AF$169="N"),0,N39*AF$168) -> 1 | AG39: =IF(OR(ISBLANK(O39),AG$169="N"),0,O39*AG$168) -> 0 | AH39: =IF(OR(ISBLANK(P39),AH$169="N"),0,P39*AH$168) -> 1 | AI39: =IF(OR(ISBLANK(Q39),AI$169="N"),0,Q39*AI$168) -> 1 | AJ39: =IF(OR(ISBLANK(R39),AJ$169="N"),0,R39*AJ$168) -> 1 | AK39: =IF(OR(ISBLANK(S39),AK$169="N"),0,S39*AK$168) -> 0 | ... AN39: =IF(OR(ISBLANK(V39),AN$169="N"),0,V39*AN$168) -> 4 | AO39: =ROUND(SUM(W39:AN39),1) -> 25.1 | AP39: =ROUND(SUM(X39:AN39),1) -> 25.1
A40: Elite Robots | B40: EC63 | C40: China | D40: 14280 | E40: 13 | F40: 0.02 | G40: 3 | H40: 6 | I40: 624 | J40: 1 | K40: propr, open, mult | L40: {=INDEX(DataValidation!$B$2:$B$11, _xlfn.XMATCH(K40, DataValidation!$A$2:$A$11))} -> 3 | M40: 0 | N40: 1 | O40: 1 | P40: 1 | Q40: 1 | R40: 1 | S40: 0 | T40: 0 | U40: 0 | V40: 2 | W40: =IF(OR(ISBLANK(D40),W$169="N"),0,(W$170-D40)*W$168) -> 4.7626667 | X40: =IF(OR(ISBLANK(E40),X$169="N"),0,(X$170-E40)*X$168) -> 3.48 | Y40: =IF(OR(ISBLANK(F40),Y$169="N"),0,(Y$170-F40)*Y$168) -> 1.6 | Z40: =IF(OR(ISBLANK(G40),Z$169="N"),0,G40*Z$168) -> 0.6 | AA40: =IF(OR(ISBLANK(H40),AA$169="N"),0,H40*AA$168) -> 3 | AB40: =IF(OR(ISBLANK(I40),AB$169="N"),0,I40*AB$168) -> 2.08 | AC40: =IF(OR(ISBLANK(J40),AC$169="N"),0,J40*AC$168) -> 1 | AD40: =IF(OR(ISBLANK(L40),AD$169="N"),0,L40*AD$168) -> 3 | AE40: =IF(OR(ISBLANK(M40),AE$169="N"),0,M40*AE$168) -> 0 | AF40: =IF(OR(ISBLANK(N40),AF$169="N"),0,N40*AF$168) -> 1 | AG40: =IF(OR(ISBLANK(O40),AG$169="N"),0,O40*AG$168) -> 1 | AH40: =IF(OR(ISBLANK(P40),AH$169="N"),0,P40*AH$168) -> 1 | AI40: =IF(OR(ISBLANK(Q40),AI$169="N"),0,Q40*AI$168) -> 1 | AJ40: =IF(OR(ISBLANK(R40),AJ$169="N"),0,R40*AJ$168) -> 1 | AK40: =IF(OR(ISBLANK(S40),AK$169="N"),0,S40*AK$168) -> 0 | ... AN40: =IF(OR(ISBLANK(V40),AN$169="N"),0,V40*AN$168) -> 4 | AO40: =ROUND(SUM(W40:AN40),1) -> 28.5 | AP40: =ROUND(SUM(X40:AN40),1) -> 23.8
A41: Elite Robots | B41: EC616 | C41: China | D41: 25800 | E41: 32.5 | F41: 0.03 | G41: 16 | H41: 6 | I41: 954 | J41: 1 | K41: propr, open, mult | L41: {=INDEX(DataValidation!$B$2:$B$11, _xlfn.XMATCH(K41, DataValidation!$A$2:$A$11))} -> 3 | M41: 0 | N41: 1 | O41: 1 | P41: 1 | Q41: 1 | R41: 1 | S41: 0 | T41: 0 | U41: 0 | V41: 2 | W41: =IF(OR(ISBLANK(D41),W$169="N"),0,(W$170-D41)*W$168) -> 3.2266667 | X41: =IF(OR(ISBLANK(E41),X$169="N"),0,(X$170-E41)*X$168) -> 2.7 | Y41: =IF(OR(ISBLANK(F41),Y$169="N"),0,(Y$170-F41)*Y$168) -> 1.4 | Z41: =IF(OR(ISBLANK(G41),Z$169="N"),0,G41*Z$168) -> 3.2 | AA41: =IF(OR(ISBLANK(H41),AA$169="N"),0,H41*AA$168) -> 3 | AB41: =IF(OR(ISBLANK(I41),AB$169="N"),0,I41*AB$168) -> 3.18 | AC41: =IF(OR(ISBLANK(J41),AC$169="N"),0,J41*AC$168) -> 1 | AD41: =IF(OR(ISBLANK(L41),AD$169="N"),0,L41*AD$168) -> 3 | AE41: =IF(OR(ISBLANK(M41),AE$169="N"),0,M41*AE$168) -> 0 | AF41: =IF(OR(ISBLANK(N41),AF$169="N"),0,N41*AF$168) -> 1 | AG41: =IF(OR(ISBLANK(O41),AG$169="N"),0,O41*AG$168) -> 1 | AH41: =IF(OR(ISBLANK(P41),AH$169="N"),0,P41*AH$168) -> 1 | AI41: =IF(OR(ISBLANK(Q41),AI$169="N"),0,Q41*AI$168) -> 1 | AJ41: =IF(OR(ISBLANK(R41),AJ$169="N"),0,R41*AJ$168) -> 1 | AK41: =IF(OR(ISBLANK(S41),AK$169="N"),0,S41*AK$168) -> 0 | ... AN41: =IF(OR(ISBLANK(V41),AN$169="N"),0,V41*AN$168) -> 4 | AO41: =ROUND(SUM(W41:AN41),1) -> 29.7 | AP41: =ROUND(SUM(X41:AN41),1) -> 26.5
...

Sheet Ranking
A1: Rank | B1: Score | C1: Manufacturer | D1: Model | E1: Country | F1: Cost | G1: Difference | J1: Ranking changes depending on excluded criteria in Scores-sheet
A2: =_xlfn.RANK.EQ(B2,$B$2:$B$162) -> 1 | B2: {=_xlfn.SORTBY(Scores!AO2:AO162,Scores!AO2:AO162,-1)} -> 30.8 | C2: {=_xlfn.SORTBY(Scores!A2:D162,Scores!AO2:AO162,-1)} -> JAKA | D2: Ai 18 | E2: Germany | F2: 26450 | G2: =B2-$B$2 -> 0
A3: =_xlfn.RANK.EQ(B3,$B$2:$B$162) -> 2 | B3: 30.3 | C3: JAKA | D3: Ai 12 | E3: Germany | F3: 25440 | G3: =B3-$B$2 -> -0.5
A4: =_xlfn.RANK.EQ(B4,$B$2:$B$162) -> 3 | B4: 30.2 | C4: JAKA | D4: Zu 18s | E4: Germany | F4: 31310 | G4: =B4-$B$2 -> -0.6
A5: =_xlfn.RANK.EQ(B5,$B$2:$B$162) -> 4 | B5: 30.1 | C5: JAKA | D5: Zu 18 | E5: Germany | F5: 24500 | G5: =B5-$B$2 -> -0.7
A6: =_xlfn.RANK.EQ(B6,$B$2:$B$162) -> 5 | B6: 30 | C6: Elite Robots | D6: EC612 | E6: China | F6: 23205 | G6: =B6-$B$2 -> -0.8
A7: =_xlfn.RANK.EQ(B7,$B$2:$B$162) -> 5 | B7: 30 | C7: JAKA | D7: Pro 16 | E7: Germany | F7: 26710 | G7: =B7-$B$2 -> -0.8
A8: =_xlfn.RANK.EQ(B8,$B$2:$B$162) -> 7 | B8: 29.8 | C8: JAKA | D8: Pro 12 | E8: Germany | F8: 23560 | G8: =B8-$B$2 -> -1
A9: =_xlfn.RANK.EQ(B9,$B$2:$B$162) -> 8 | B9: 29.7 | C9: Elite Robots | D9: EC616 | E9: China | F9: 25800 | G9: =B9-$B$2 -> -1.1
A10: =_xlfn.RANK.EQ(B10,$B$2:$B$162) -> 8 | B10: 29.7 | C10: JAKA | D10: Zu 12s | E10: Germany | F10: 30300 | G10: =B10-$B$2 -> -1.1
A11: =_xlfn.RANK.EQ(B11,$B$2:$B$162) -> 10 | B11: 29.6 | C11: AUBO Robotics | D11: AUBO i20 | E11: USA | F11: 30000 | G11: =B11-$B$2 -> -1.2
A12: =_xlfn.RANK.EQ(B12,$B$2:$B$162) -> 10 | B12: 29.6 | C12: JAKA | D12: Zu 12 | E12: Germany | F12: 23500 | G12: =B12-$B$2 -> -1.2
A13: =_xlfn.RANK.EQ(B13,$B$2:$B$162) -> 12 | B13: 29.5 | C13: Fanuc | D13: CRX-20iA/L | E13: Japan | F13: 45000 | G13: =B13-$B$2 -> -1.3
A14: =_xlfn.RANK.EQ(B14,$B$2:$B$162) -> 13 | B14: 29.4 | C14: Dobot | D14: CR10 | E14: China | F14: 21540 | G14: =B14-$B$2 -> -1.4
... A162: =_xlfn.RANK.EQ(B162,$B$2:$B$162) -> 161 | B162: -7.3 | C162: Comau | D162: Aura | E162: Italy | F162: 0 | G162: =B162-$B$2 -> -38.1

Sheet GraphsAndCharts
A1: Industrial Robot Installations (IFR)
A2: Industry | B2: 2023 | C2: 2022 | D2: Percent
A3: Automobilindustrie | B3: 135 | C3: 136 | D3: =100-B3*100/C3 -> 0.73529412
A4: Elektronikindustrie | B4: 126 | C4: 157 | D4: =100-B4*100/C4 -> 19.745223
A5: Metall- und Maschinenbau | B5: 77 | C5: 66 | D5: =100-B5*100/C5 -> -16.666667
A6: Plastik- und Chemieindustrie | B6: 22 | C6: 24 | D6: =100-B6*100/C6 -> 8.3333333
A7: Lebensmittelindustrie | B7: 15 | C7: 15 | D7: =100-B7*100/C7 -> 0
A8: Sonstige | B8: 75 | C8: 61 | D8: =100-B8*100/C8 -> -22.95082
A9: unbestimmt | B9: 91 | C9: 94 | D9: =100-B9*100/C9 -> 3.1914894
A11: Application of Cobots
B12: Material Handling | C12: Welding | D12: Assembly | E12: Dispensing | F12: Processing | G12: Service | H12: Other Application
A13: Total | B13: {=Scores!N163:T164} -> 156 | C13: 64 | D13: 125 | E13: 143 | F13: 77 | G13: 26 | H13: 80
A14: Percentage | B14: 0.969 | C14: 0.398 | D14: 0.776 | E14: 0.888 | F14: 0.478 | G14: 0.161 | H14: 0.497
A16: Statistical Values of quantitative Criteria
A17: Criterion | B17: Min | C17: Max | D17: Mean | E17: Median | F17: Mode | G17: Count
A18: Cost (EUR) | B18: {=TRANSPOSE(Scores!D166:J167)} -> 2900 | C18: 54333 | D18: {=TRANSPOSE(Scores!D163:J165)} -> 28585.44 | E18: 28107.5 | F18: 37500 | G18: =COUNT(Scores!D$2:D$162) -> 116
A19: Mass (kg) | B19: 4 | C19: 1615 | D19: 50.166875 | E19: 33.5 | F19: 23 | G19: =COUNT(Scores!E$2:E$162) -> 160
A20: Repeat (mm) | B20: 0.01 | C20: 1 | D20: 0.071379747 | E20: 0.03 | F20: 0.02 | G20: =COUNT(Scores!F$2:F$162) -> 158
A21: Payload (kg) | B21: 0.5 | C21: 170 | D21: 10.953125 | E21: 8 | F21: 5 | G21: =COUNT(Scores!G$2:G$162) -> 160
A22: DoF | B22: 4 | C22: 7 | D22: 6.0062893 | E22: 6 | F22: 6 | G22: =COUNT(Scores!H$2:H$162) -> 159
A23: Reach (mm) | B23: 343 | C23: 2790 | D23: 1095.7381 | E23: 967.5 | F23: 1300 | G23: =COUNT(Scores!I$2:I$162) -> 159
A24: Arms | B24: 1 | C24: 2 | D24: 1.0248447 | E24: 1 | F24: 1 | G24: =COUNT(Scores!J$2:J$162) -> 161
A26: Scatterplot of Cost and Score (changes according to criteria selection in Scores-Sheet) | H26: Histogramm of distribution in bins of size 5 (changes according to criteria selection in Scores-Sheet)
A43: Scatterplot of Cost and Score (cost excluded)
A60: Country Distribution | D60: Sorted Country Distribution
A61: Country Distribution | B61: Count | C61: Percentage | D61: Country | E61: Total | F61: Percentage
A62: {=_xlfn.UNIQUE(Scores!C2:C162)} -> Switzerland | B62: =COUNTIF(Scores!$C$2:$C$162,A62) -> 10 | C62: =B62/RawCobots!$D$182 -> 0.062111801 | D62: {=_xlfn.SORTBY(A62:C71,B62:B71,-1)} -> Germany | E62: 48 | F62: 0.29813665
A63: Germany | B63: =COUNTIF(Scores!$C$2:$C$162,A63) -> 48 | C63: =B63/RawCobots!$D$182 -> 0.29813665 | D63: Japan | E63: 34 | F63: 0.21118012
A64: USA | B64: =COUNTIF(Scores!$C$2:$C$162,A64) -> 8 | C64: =B64/RawCobots!$D$182 -> 0.049689441 | D64: China | E64: 27 | F64: 0.16770186
A65: Italy | B65: =COUNTIF(Scores!$C$2:$C$162,A65) -> 2 | C65: =B65/RawCobots!$D$182 -> 0.01242236 | D65: South Korea | E65: 13 | F65: 0.080745342
A66: Taiwan | B66: =COUNTIF(Scores!$C$2:$C$162,A66) -> 7 | C66: =B66/RawCobots!$D$182 -> 0.043478261 | D66: Denmark | E66: 11 | F66: 0.068322981
A67: Japan | B67: =COUNTIF(Scores!$C$2:$C$162,A67) -> 34 | C67: =B67/RawCobots!$D$182 -> 0.21118012 | D67: Switzerland | E67: 10 | F67: 0.062111801
A68: China | B68: =COUNTIF(Scores!$C$2:$C$162,A68) -> 27 | C68: =B68/RawCobots!$D$182 -> 0.16770186 | D68: USA | E68: 8 | F68: 0.049689441
A69: South Korea | B69: =COUNTIF(Scores!$C$2:$C$162,A69) -> 13 | C69: =B69/RawCobots!$D$182 -> 0.080745342 | D69: Taiwan | E69: 7 | F69: 0.043478261
A70: Denmark | B70: =COUNTIF(Scores!$C$2:$C$162,A70) -> 11 | C70: =B70/RawCobots!$D$182 -> 0.068322981 | D70: Italy | E70: 2 | F70: 0.01242236
